Workbook

Sheet ស្ថិតិលទ្ធផលសិក្សាតាមនិទ្ទេស
A1: ព្រះរាជាណាចក្រកម្ពុជា
A2: ជាតិ សាសនា ព្រះមហាក្សត្រ
A3: 6
A4: ក្រសួងអប់រំ យុវជន និងកីឡា
A5: មន្ទីរអប់រំ យុវជន និងកីឡា ខេត្តបន្ទាយមានជ័យ
A6: វិទ្យាល័យចំណេះទូទៅនិងបច្ចេកទេស ឯកជនដុនបូស្កូប៉ោយប៉ែត
A7: របាយការណ៍
A8: ស្តីពី
A9: ស្ថិតិលទ្ធផលការសិក្សាតាមនិទ្ទេសរបស់សិស្សផ្នែកបច្ចេកទេសសម្រាខែមីនា ឆ្នាំសិក្សា ២០២៥-២០២៦
A10: ១- លទ្ធផលប្រទ្បងខែមីនា | H10: ​
A11: ឈ្មោះសាលា | C11: មុខជំនាញ | D11: ឆ្នាំទី | E11: សិស្សរៀននៅឆមាសទី២ | G11: សិស្សបានប្រទ្បង | K11: និទ្ទេស | U11: សិស្សមិនបានប្រទ្បង (NA)
G12: សិស្សជាប់មធ្យមភាគ | I12: សិស្សធ្លាក់មធ្យមភាគ (F) | K12: និទ្ទេសA | M12: និទ្ទេសB | O12: និទ្ទេសC | Q12: និទ្ទេសD | S12: និទ្ទេសE
E13: សរុប | F13: ស្រី | G13: សរុប | H13: ស្រី | I13: សរុប | J13: ស្រី | K13: សរុប | L13: ស្រី | M13: សរុប | N13: ស្រី | O13: សរុប | P13: ស្រី | Q13: សរុប | R13: ស្រី | S13: សរុប | T13: ស្រី | U13: សរុប | V13: ស្រី
A14: វិទ្យាល័យចំណេះទូទៅនិងបច្ចេកទេស ឯកជនដុនបូស្កូប៉ោយប៉ែត | C14: អគ្គិសនី | D14: 1 | E14: =អគ្គិសនី១!B47 -> 22 | F14: =អគ្គិសនី១!C47 -> 5 | G14: =SUM(K14,M14,O14,Q14,S14) -> 17 | H14: =SUM(L14,N14,P14,R14,T14) -> 1 | I14: =អគ្គិសនី១!F47 -> 0 | J14: =អគ្គិសនី១!G47 -> 0 | K14: =អគ្គិសនី២!H44 -> 0 | L14: =អគ្គិសនី២!I44 -> 0 | M14: =អគ្គិសនី២!J44 -> 0 | N14: =អគ្គិសនី២!K44 -> 0 | O14: =អគ្គិសនី២!L44 -> 4 | P14: =អគ្គិសនី២!M44 -> 1 | Q14: =អគ្គិសនី២!N44 -> 5 | R14: =អគ្គិសនី២!O44 -> 0 | ... T14: =អគ្គិសនី២!Q44 -> 0 | U14: =អគ្គិសនី១!R47 -> 1 | V14: =អគ្គិសនី១!S47 -> 0
D15: 2 | E15: =អគ្គិសនី២!B44 -> 18 | F15: =អគ្គិសនី២!C44 -> 1 | G15: =SUM(K15,M15,O15,Q15,S15) -> 14 | H15: =SUM(L15,N15,P15,R15,T15) -> 0 | I15: =អគ្គិសនី២!F44 -> 0 | J15: =អគ្គិសនី២!G44 -> 0 | K15: =អគ្គិសនី៣!H43 -> 0 | L15: =អគ្គិសនី៣!I43 -> 0 | M15: =អគ្គិសនី៣!J43 -> 0 | N15: =អគ្គិសនី៣!K43 -> 0 | O15: =អគ្គិសនី៣!L43 -> 0 | P15: =អគ្គិសនី៣!M43 -> 0 | Q15: =អគ្គិសនី៣!N43 -> 4 | R15: =អគ្គិសនី៣!O43 -> 0 | ... T15: =អគ្គិសនី៣!Q43 -> 0 | U15: =អគ្គិសនី២!R44 -> 1 | V15: =អគ្គិសនី២!S44 -> 0
D16: 3 | E16: =អគ្គិសនី៣!B43 -> 14 | F16: =អគ្គិសនី៣!C43 -> 0 | G16: =SUM(K16,M16,O16,Q16,S16) -> 21 | H16: =SUM(L16,N16,P16,R16,T16) -> 5 | I16: =អគ្គិសនី៣!F43 -> 0 | J16: =អគ្គិសនី៣!G43 -> 0 | K16: =អគ្គិសនី១!H47 -> 0 | L16: =អគ្គិសនី១!I47 -> 0 | M16: =អគ្គិសនី១!J47 -> 0 | N16: =អគ្គិសនី១!K47 -> 0 | O16: =អគ្គិសនី១!L47 -> 3 | P16: =អគ្គិសនី១!M47 -> 2 | Q16: =អគ្គិសនី១!N47 -> 7 | R16: =អគ្គិសនី១!O47 -> 2 | ... T16: =អគ្គិសនី១!Q47 -> 1 | U16: =អគ្គិសនី៣!R43 -> 0 | V16: =អគ្គិសនី៣!S43 -> 0
C17: សរុប | E17: =SUM(E14:E16) -> 54 | F17: =SUM(F14:F16) -> 6 | G17: =SUM(G14:G16) -> 52 | H17: =SUM(H14:H16) -> 6 | I17: =SUM(I14:I16) -> 0 | J17: =SUM(J14:J16) -> 0 | K17: =SUM(K14:K16) -> 0 | L17: =SUM(L14:L16) -> 0 | ... V17: =SUM(V14:V16) -> 0
C18: កុំព្យូទ័រ | D18: 1 | E18: =កុំព្យទ័រ១!B55 -> 29 | F18: =កុំព្យទ័រ១!C55 -> 20 | G18: =SUM(K18+M18+O18+Q18+S18) -> 27 | H18: =SUM(L18+N18+P18+R18+T18) -> 19 | I18: =កុំព្យទ័រ១!F55 -> 0 | J18: =កុំព្យទ័រ១!G55 -> 0 | K18: =កុំព្យូទ័រ២!H53 -> 0 | L18: =កុំព្យូទ័រ២!I53 -> 0 | M18: =កុំព្យូទ័រ២!J53 -> 11 | N18: =កុំព្យូទ័រ២!K53 -> 9 | O18: =កុំព្យូទ័រ២!L53 -> 10 | P18: =កុំព្យូទ័រ២!M53 -> 8 | Q18: =កុំព្យូទ័រ២!N53 -> 6 | R18: =កុំព្យូទ័រ២!O53 -> 2 | ... T18: =កុំព្យូទ័រ២!Q53 -> 0 | U18: =កុំព្យទ័រ១!R55 -> 0 | V18: =កុំព្យទ័រ១!S55 -> 0
D19: 2 | E19: =កុំព្យូទ័រ២!B53 -> 27 | F19: =កុំព្យូទ័រ២!C53 -> 19 | G19: =SUM(K19+M19+O19+Q19+S19) -> 24 | H19: =SUM(L19+N19+P19+R19+T19) -> 17 | I19: =កុំព្យូទ័រ២!F53 -> 0 | J19: =កុំព្យូទ័រ២!G53 -> 0 | K19: =កុំព្យទ័រ៣!H50 -> 1 | L19: =កុំព្យទ័រ៣!I50 -> 0 | M19: =កុំព្យទ័រ៣!J50 -> 9 | N19: =កុំព្យទ័រ៣!K50 -> 8 | O19: =កុំព្យទ័រ៣!L50 -> 8 | P19: =កុំព្យទ័រ៣!M50 -> 5 | Q19: =កុំព្យទ័រ៣!N50 -> 5 | R19: =កុំព្យទ័រ៣!O50 -> 3 | ... T19: =កុំព្យទ័រ៣!Q50 -> 1 | U19: =កុំព្យូទ័រ២!R53 -> 0 | V19: =កុំព្យូទ័រ២!S53 -> 0
D20: 3 | E20: =កុំព្យទ័រ៣!B50 -> 24 | F20: =កុំព្យទ័រ៣!C50 -> 17 | G20: =SUM(K20+M20+O20+Q20+S20) -> 29 | H20: =SUM(L20+N20+P20+R20+T20) -> 20 | I20: =កុំព្យទ័រ៣!F50 -> 0 | J20: =កុំព្យទ័រ៣!G50 -> 0 | K20: =កុំព្យទ័រ១!H55 -> 0 | L20: =កុំព្យទ័រ១!I55 -> 0 | M20: =កុំព្យទ័រ១!J55 -> 8 | N20: =កុំព្យទ័រ១!K55 -> 3 | O20: =កុំព្យទ័រ១!L55 -> 11 | P20: =កុំព្យទ័រ១!M55 -> 8 | Q20: =កុំព្យទ័រ១!N55 -> 7 | R20: =កុំព្យទ័រ១!O55 -> 6 | ... T20: =កុំព្យទ័រ១!Q55 -> 3 | U20: =កុំព្យទ័រ៣!R50 -> 0 | V20: =កុំព្យទ័រ៣!S50 -> 0
C21: សរុប | E21: =SUM(E18:E20) -> 80 | F21: =SUM(F18:F20) -> 56 | G21: =SUM(G18:G20) -> 80 | H21: =SUM(H18:H20) -> 56 | I21: =SUM(I18:I20) -> 0 | J21: =SUM(J18:J20) -> 0 | K21: =SUM(K18:K20) -> 1 | L21: =SUM(L18:L20) -> 0 | ... V21: =SUM(V18:V20) -> 0
C22: មេកានិច | D22: 1 | E22: =មេកានិច១!B43 -> 10 | F22: =មេកានិច១!C43 -> 6 | G22: =SUM(K22+M22+O22+Q22+S22) -> 14 | H22: =SUM(L22+N22+P22+R22+T22) -> 5 | I22: =មេកានិច១!F43 -> 0 | J22: =មេកានិច១!G43 -> 0 | K22: =មេកានិច២!H48 -> 0 | L22: =មេកានិច២!I48 -> 0 | M22: =មេកានិច២!J48 -> 2 | N22: =មេកានិច២!K48 -> 0 | O22: =មេកានិច២!L48 -> 2 | P22: =មេកានិច២!M48 -> 2 | Q22: =មេកានិច២!N48 -> 5 | R22: =មេកានិច២!O48 -> 1 | ... T22: =មេកានិច២!Q48 -> 2 | U22: =មេកានិច១!R43 -> 2 | V22: =មេកានិច១!S43 -> 0
D23: 2 | E23: =មេកានិច២!B48 -> 15 | F23: =មេកានិច២!C48 -> 5 | G23: =SUM(K23+M23+O23+Q23+S23) -> 0 | H23: =SUM(L23+N23+P23+R23+T23) -> 0 | I23: =មេកានិច២!F48 -> 0 | J23: =មេកានិច២!G48 -> 0 | K23: =មេកានិច២!H49 -> 0 | L23: =មេកានិច២!I49 -> 0 | M23: =មេកានិច២!J49 -> 0 | N23: =មេកានិច២!K49 -> 0 | O23: =មេកានិច២!L49 -> 0 | P23: =មេកានិច២!M49 -> 0 | Q23: =មេកានិច២!N49 -> 0 | R23: =មេកានិច២!O49 -> 0 | ... T23: =មេកានិច២!Q49 -> 0 | U23: =មេកានិច២!R48 -> 1 | V23: =មេកានិច២!S48 -> 0
D24: 3
C25: សរុប | E25: =SUM(E22:E24) -> 25 | F25: =SUM(F22:F24) -> 11 | G25: =SUM(G22:G24) -> 14 | H25: =SUM(H22:H24) -> 5 | I25: =SUM(I22:I24) -> 0 | J25: =SUM(J22:J24) -> 0 | K25: =SUM(K22:K24) -> 0 | L25: =SUM(L22:L24) -> 0 | ... V25: =SUM(V22:V24) -> 0
D26: 1
D27: 2
D28: 3
C29: សរុប | E29: =SUM(E26:E28) -> 0 | F29: =SUM(F26:F28) -> 0 | G29: =SUM(G26:G28) -> 0 | H29: =SUM(H26:H28) -> 0 | I29: =SUM(I26:I28) -> 0 | J29: =SUM(J26:J28) -> 0 | K29: =SUM(K26:K28) -> 0 | L29: =SUM(L26:L28) -> 0 | ... V29: =SUM(V26:V28) -> 0
C30: សរុបរួម៤ជំនាញ | E30: =SUM(E17,E21,E25,E29) -> 159 | F30: =SUM(F17,F21,F25,F29) -> 73 | G30: =SUM(G25,G21,G17) -> 146 | H30: =SUM(H17,H21,H25,H29) -> 67 | I30: =SUM(I17,I21,I25,I29) -> 0 | J30: =SUM(J17,J21,J25,J29) -> 0 | K30: =SUM(K17,K21,K25,K29) -> 1 | L30: =SUM(L17,L21,L25,L29) -> 0 | M30: =SUM(M17,M21,M25,M29) -> 30 | N30: =SUM(N17,N21,N25,N29) -> 20 | O30: =SUM(O17,O21,O25,O29) -> 38 | ... V30: =SUM(V17,V21,V25,V29) -> 0
C31: សរុបមធ្យមភាគជាភាគរយ(%) | G31: =IF(G30=0,0,G30/E30) -> 0.91823899 | H31: =IF(H30=0,0,H30/F30) -> 0.91780822 | I31: =IF(I30=0,0,I30/E30) -> 0 | J31: =IF(J30=0,0,J30/F30) -> 0 | K31: =IF(K30=0,0,K30/E30) -> 0.0062893082 | L31: =IF(L30=0,0,L30/F30) -> 0 | M31: =IF(M30=0,0,M30/E30) -> 0.18867925 | N31: =IF(N30=0,0,N30/F30) -> 0.2739726 | O31: =IF(O30=0,0,O30/E30) -> 0.23899371 | P31: =IF(P30=0,0,P30/F30) -> 0.35616438 | Q31: =IF(Q30=0,0,Q30/E30) -> 0.24528302 | R31: =IF(R30=0,0,R30/F30) -> 0.19178082 | S31: =IF(S30=0,0,S30/E30) -> 0.23899371 | T31: =IF(T30=0,0,T30/F30) -> 0.095890411 | U31: =IF(U30=0,0,U30/E30) -> 0.031446541 | V31: =IF(V30=0,0,V30/F30) -> 0
A34: **សំគាល់៖ សិស្សមិនបានប្រឡងគឺសិស្សមិនបានប្រឡងសូម្បីតែមួយមុខវិជ្ជា (NA)
A35: ២- ក្រាបលទ្ធផលប្រឡងខែ
A36: ក. ក្រាបការប្រៀបធៀបលទ្ធផលប្រទ្បងរបស់សិស្សសម្រាប់ខែចាស់ និងខែថ្មី (ឧបសម្ព័ន្ធទី១)
A37: ឧទាហរណ៍៖ ការប្រៀបធៀបលទ្ធផលសរុបរបស់សិស្សសម្រាប់ខែ….. និង…...
B51: * បញ្ជាក់៖ | D51: សូមបញ្ចូលទិន្នន័យលទ្ធផលសរុបសម្រាប់ខែចាស់ចូលទៅក្នុងតារាងឧបសម្ព័ន្ធទី១
A52: ខ. តារាងពិន្ទុប្រឡងប្រចាំខែ…. (ឧបសម្ព័ន្ធទី២)
A53: គ. ក្រាបលទ្ធផលការសិក្សារបស់សិស្សតាមជំនាញនីមួយៗ ប្រចាំខែ…..(ឧបសម្ព័ន្ធទី៣)
A54: ឃ. ក្រាបសរុបរួមនៃលទ្ធផលការសិក្សារបស់សិស្សបច្ចេកទេស ប្រចាំខែ…..(ឧបសម្ព័ន្ធទី៤)
A55: ៣- បញ្ហាប្រឈម
...

Sheet ប្រៀបធៀបលទ្ធផលសរុប
A3: ព្រះរាជាណាចក្រកម្ពុជា
A4: ជាតិ សាសនា ព្រះមហាក្សត្រ
A5: 6
A6: ក្រសួងអប់រំ យុវជន និងកីឡា | S6: ឧបសម្ព័ន្ធទី១
A7: =ស្ថិតិលទ្ធផលសិក្សាតាមនិទ្ទេស!A5 -> មន្ទីរអប់រំ យុវជន និងកីឡា ខេត្តបន្ទាយមានជ័យ
A8: =ស្ថិតិលទ្ធផលសិក្សាតាមនិទ្ទេស!A6 -> វិទ្យាល័យចំណេះទូទៅនិងបច្ចេកទេស ឯកជនដុនបូស្កូប៉ោយប៉ែត
A10: =ស្ថិតិលទ្ធផលសិក្សាតាមនិទ្ទេស!A9 -> ស្ថិតិលទ្ធផលការសិក្សាតាមនិទ្ទេសរបស់សិស្សផ្នែកបច្ចេកទេសសម្រាខែមីនា ឆ្នាំសិក្សា ២០២៥-២០២៦
A11: ឧទាហរណ៍៖ ការប្រៀបធៀបលទ្ធផលសរុបរបស់សិស្សសម្រាប់ខែមីនា
A12: ខែ | B12: សិស្សរៀនឆមាសទី១ | D12: សិស្សបានប្រទ្បង | H12: និទ្ទេស | T12: ផ្សេងៗ
D13: សិស្សប្រទ្បងជាប់ | F13: សិស្សប្រទ្បងធ្លាក់(F) | H13: និទ្ទេសA | J13: និទ្ទេសB | L13: និទ្ទេសC | N13: និទ្ទេសD | P13: និទ្ទេសE | R13: NA
B14: សរុប | C14: ស្រី | D14: សរុប | E14: ស្រី | F14: សរុប | G14: ស្រី | H14: សរុប | I14: ស្រី | J14: សរុប | K14: ស្រី | L14: សរុប | M14: ស្រី | N14: សរុប | O14: ស្រី | P14: សរុប | Q14: ស្រី | R14: សរុប | S14: ស្រី
A15: ឆមាសទី១ | B15: 170 | C15: 78 | D15: 159 | E15: 73 | F15: 0 | G15: 0 | H15: 3 | I15: 1 | J15: 19 | K15: 10 | L15: 40 | M15: 25 | N15: 51 | O15: 21 | P15: 46 | Q15: 16 | R15: 11 | S15: 5
A16: ខែមីនា | B16: =ស្ថិតិលទ្ធផលសិក្សាតាមនិទ្ទេស!E30 -> 159 | C16: =ស្ថិតិលទ្ធផលសិក្សាតាមនិទ្ទេស!F30 -> 73 | D16: =SUM(H16+J16+L16+N16+P16) -> 146 | E16: =SUM(I16+K16+M16+O16+Q16) -> 67 | F16: =ស្ថិតិលទ្ធផលសិក្សាតាមនិទ្ទេស!I30 -> 0 | G16: =ស្ថិតិលទ្ធផលសិក្សាតាមនិទ្ទេស!J30 -> 0 | H16: =ស្ថិតិលទ្ធផលសិក្សាតាមនិទ្ទេស!K30 -> 1 | I16: =ស្ថិតិលទ្ធផលសិក្សាតាមនិទ្ទេស!L30 -> 0 | J16: =ស្ថិតិលទ្ធផលសិក្សាតាមនិទ្ទេស!M30 -> 30 | K16: =ស្ថិតិលទ្ធផលសិក្សាតាមនិទ្ទេស!N30 -> 20 | L16: =ស្ថិតិលទ្ធផលសិក្សាតាមនិទ្ទេស!O30 -> 38 | M16: =ស្ថិតិលទ្ធផលសិក្សាតាមនិទ្ទេស!P30 -> 26 | ... S16: =ស្ថិតិលទ្ធផលសិក្សាតាមនិទ្ទេស!V30 -> 0
M19: =អគ្គិសនី១!O48 -> ថ្ងៃអង្គារ ១៣កើត ខែចេត្រ ឆ្នាំម្សាញ់ សប្តស័ក ព.ស ២៥៦៩
M20: =អគ្គិសនី១!P49 -> ធ្វើនៅដុនបូស្កូប៉ោយប៉ែត ថ្ងៃទី៣១ខែ មីនាឆ្នាំ ២០២៦
M21: អ្នកធ្វើតារាង

Sheet មេកានិច១
A1: ព្រះរាជាណាចក្រកម្ពុជា
A2: ជាតិ សាសនា ព្រះមហាក្សត្រ
A3: 6
A4: ក្រសួងអប់រំ យុវជន និងកីឡា | U4: ឧបសម្ព័ន្ធទី២
A5: =ស្ថិតិលទ្ធផលសិក្សាតាមនិទ្ទេស!A5 -> មន្ទីរអប់រំ យុវជន និងកីឡា ខេត្តបន្ទាយមានជ័យ
A6: =ស្ថិតិលទ្ធផលសិក្សាតាមនិទ្ទេស!A6 -> វិទ្យាល័យចំណេះទូទៅនិងបច្ចេកទេស ឯកជនដុនបូស្កូប៉ោយប៉ែត
A7: តារាងពិន្ទុប្រឡងប្រចាំខែមីនា របស់សិស្សផ្នែក មេកានិច ឆ្នាំទី១
A8: ឆ្នាំសិក្សា ២០២៥- ២០២៦
A9: ល.រ | B9: គោត្តនាម | C9: និងនាម | D9: ភេទ | E9: ថ្ងៃខែឆ្នាំកំណើត | G9: មុខវិជ្ជា | Q9: សរុប | R9: មធ្យមភាគ | S9: និទ្ទេស | T9: ចំណាត់ថ្នាក់ | U9: អវត្តមាន
G10: ខ្មែរ | H10: គណិត | I10: រូប​ | J10: អង់គ្លេស | K10: ពលរដ្ឋ | L10: កីឡា | M10: ទ្រឹស្ដីទី១ | N10: ទ្រឹស្ដីទី២ | O10: ផ្ទាល់មាត់ | P10: អនុវត្ត
U11: មានច្បាប់ | V11: អត់ច្បាប់ | W11: សរុប
A12: 1 | B12: កន | C12: ប៊ុនរ៉ុង | D12: ប | E12: ៩ កញ្ញា ២០០៩ | G12: 0 | H12: 0 | I12: 0 | J12: 0 | K12: 0 | L12: 0 | M12: 0 | N12: 0 | O12: 0 | P12: 0 | Q12: =SUM(G12:P12)-W12 -> 0 | R12: =Q12/14.5 -> 0 | S12: =IF(R12>=50*0.9,"A",IF(R12>=50*0.8,"B",IF(R12>=50*0.7,"C",IF(R12>=50*0.6,"D",IF(R12>=50*0.5,"E",IF(Q12=0,"NA","F")))))) -> NA | T12: =RANK(R12,$R$12:$R$21) -> 9 | U12: 0 | V12: 0 | W12: =SUM(U12:V12) -> 0
A13: 2 | B13: ជា | C13: សុខលៃ | D13: ស | E13: ៣០ ឧសភា ២០០៨ | G13: 44 | H13: 10 | I13: 15 | J13: 27 | K13: 24 | L13: 20 | M13: 75 | N13: 69 | O13: 65 | P13: 110 | Q13: =SUM(G13:P13)-W13 -> 459 | R13: =Q13/14.5 -> 31.655172 | S13: =IF(R13>=50*0.9,"A",IF(R13>=50*0.8,"B",IF(R13>=50*0.7,"C",IF(R13>=50*0.6,"D",IF(R13>=50*0.5,"E",IF(Q13=0,"NA","F")))))) -> D | T13: =RANK(R13,$R$12:$R$21) -> 3 | U13: 0 | V13: 0 | W13: =SUM(U13:V13) -> 0
A14: 3 | B14: ឈីន | C14: ស៊ីវជីង | D14: ស | E14: ០៩ កញ្ញា ២០០៩ | G14: 21 | H14: 2 | I14: 18 | J14: 44 | K14: 24 | L14: 20 | M14: 61 | N14: 60 | O14: 60 | P14: 115 | Q14: =SUM(G14:P14)-W14 -> 424 | R14: =Q14/14.5 -> 29.241379 | S14: =IF(R14>=50*0.9,"A",IF(R14>=50*0.8,"B",IF(R14>=50*0.7,"C",IF(R14>=50*0.6,"D",IF(R14>=50*0.5,"E",IF(Q14=0,"NA","F")))))) -> E | T14: =RANK(R14,$R$12:$R$21) -> 6 | U14: 0 | V14: 1 | W14: =SUM(U14:V14) -> 1
A15: 4 | B15: ពុំ | C15: ចាន់លាង | D15: ប | E15: ២១ តុលា ២០០៩ | G15: 26 | H15: 2 | I15: 20 | J15: 44 | K15: 24 | L15: 20 | M15: 65 | N15: 68 | O15: 70 | P15: 115 | Q15: =SUM(G15:P15)-W15 -> 452 | R15: =Q15/14.5 -> 31.172414 | S15: =IF(R15>=50*0.9,"A",IF(R15>=50*0.8,"B",IF(R15>=50*0.7,"C",IF(R15>=50*0.6,"D",IF(R15>=50*0.5,"E",IF(Q15=0,"NA","F")))))) -> D | T15: =RANK(R15,$R$12:$R$21) -> 4 | U15: 0 | V15: 2 | W15: =SUM(U15:V15) -> 2
A16: 5 | B16: ភា | C16: លយ | D16: ប | E16: ២៣ សីហា ២០០៩ | G16: 46 | H16: 2 | I16: 15 | J16: 50 | K16: 20 | L16: 20 | M16: 52 | N16: 50 | O16: 65 | P16: 60 | Q16: =SUM(G16:P16)-W16 -> 379 | R16: =Q16/14.5 -> 26.137931 | S16: =IF(R16>=50*0.9,"A",IF(R16>=50*0.8,"B",IF(R16>=50*0.7,"C",IF(R16>=50*0.6,"D",IF(R16>=50*0.5,"E",IF(Q16=0,"NA","F")))))) -> E | T16: =RANK(R16,$R$12:$R$21) -> 8 | U16: 1 | V16: 0 | W16: =SUM(U16:V16) -> 1
A17: 6 | B17: រ៉ាន់ | C17: ធារ៉ា | D17: ស | E17: ១៩ កញ្ញា ២០១០ | G17: 49 | H17: 2 | I17: 24 | J17: 20 | K17: 24 | L17: 20 | M17: 85 | N17: 82 | O17: 75 | P17: 88 | Q17: =SUM(G17:P17)-W17 -> 469 | R17: =Q17/14.5 -> 32.344828 | S17: =IF(R17>=50*0.9,"A",IF(R17>=50*0.8,"B",IF(R17>=50*0.7,"C",IF(R17>=50*0.6,"D",IF(R17>=50*0.5,"E",IF(Q17=0,"NA","F")))))) -> D | T17: =RANK(R17,$R$12:$R$21) -> 2 | U17: 0 | V17: 0 | W17: =SUM(U17:V17) -> 0
A18: 7 | B18: សុគន់ | C18: ចន្ធី | D18: ស | E18: ២១ កុម្ភៈ ២០០៩ | G18: 43 | H18: 18 | I18: 36 | J18: 29 | K18: 23 | L18: 20 | M18: 71 | N18: 63 | O18: 68 | P18: 110 | Q18: =SUM(G18:P18)-W18 -> 480 | R18: =Q18/14.5 -> 33.103448 | S18: =IF(R18>=50*0.9,"A",IF(R18>=50*0.8,"B",IF(R18>=50*0.7,"C",IF(R18>=50*0.6,"D",IF(R18>=50*0.5,"E",IF(Q18=0,"NA","F")))))) -> D | T18: =RANK(R18,$R$12:$R$21) -> 1 | U18: 1 | V18: 0 | W18: =SUM(U18:V18) -> 1
A19: 8 | B19: សឿន | C19: លីហេង | D19: ប | E19: ២៤ តុលា ២០១០ | G19: 0 | H19: 0 | I19: 0 | J19: 0 | K19: 0 | L19: 0 | M19: 0 | N19: 0 | O19: 0 | P19: 0 | Q19: =SUM(G19:P19)-W19 -> 0 | R19: =Q19/14.5 -> 0 | S19: =IF(R19>=50*0.9,"A",IF(R19>=50*0.8,"B",IF(R19>=50*0.7,"C",IF(R19>=50*0.6,"D",IF(R19>=50*0.5,"E",IF(Q19=0,"NA","F")))))) -> NA | T19: =RANK(R19,$R$12:$R$21) -> 9 | U19: 0 | V19: 0 | W19: =SUM(U19:V19) -> 0
A20: 9 | B20: សោម | C20: ជ័យអួយ | D20: ស | E20: ០៥ មិនា ២០០៦ | G20: 51 | H20: 6 | I20: 15 | J20: 25 | K20: 25 | L20: 20 | M20: 62 | N20: 54 | O20: 68 | P20: 60 | Q20: =SUM(G20:P20)-W20 -> 384 | R20: =Q20/14.5 -> 26.482759 | S20: =IF(R20>=50*0.9,"A",IF(R20>=50*0.8,"B",IF(R20>=50*0.7,"C",IF(R20>=50*0.6,"D",IF(R20>=50*0.5,"E",IF(Q20=0,"NA","F")))))) -> E | T20: =RANK(R20,$R$12:$R$21) -> 7 | U20: 0 | V20: 2 | W20: =SUM(U20:V20) -> 2
A21: 10 | B21: ហង់ | C21: ស្រីមួយ | D21: ស | E21: ០១ តុលា ២០០៩ | G21: 38 | H21: 2 | I21: 38 | J21: 27 | K21: 25 | L21: 20 | M21: 84 | N21: 81 | O21: 65 | P21: 60 | Q21: =SUM(G21:P21)-W21 -> 438 | R21: =Q21/14.5 -> 30.206897 | S21: =IF(R21>=50*0.9,"A",IF(R21>=50*0.8,"B",IF(R21>=50*0.7,"C",IF(R21>=50*0.6,"D",IF(R21>=50*0.5,"E",IF(Q21=0,"NA","F")))))) -> D | T21: =RANK(R21,$R$12:$R$21) -> 5 | U21: 1 | V21: 1 | W21: =SUM(U21:V21) -> 2
E22: ២៦ មិថុនា ២០០៨ | U22: 0 | V22: 0 | W22: 0
U23: 0 | V23: 0
U24: 0 | V24: 0
U25: 0 | V25: 0
U26: 0 | V26: 0
U27: 0 | V27: 0
U28: 0 | V28: 0
A29: ="បញ្ឈប់បញ្ជីត្រឹមឈ្មោះ ហង់ ស្រីមួយ "&" ចំនួនសរុប "&COUNT(A12:A21)&" នាក់"&" ក្នុងនោះស្រី "&COUNTIF(D12:D21,"ស")&" នាក់ ។" -> បញ្ឈប់បញ្ជីត្រឹមឈ្មោះ ហង់ ស្រីមួយ ចំនួនសរុប 10 នាក់ ក្នុងនោះស្រី 6 នាក់ ។
B30: * បញ្ជាក់
B31: លំដាប់ពិន្ទុ | D31: និទ្ទេស | E31: សេចក្តីពណ៌នា
B32: មធ្យមភាគអតិប្បរមា*0.9 | D32: A | E32: ល្អប្រសើរ
B33: មធ្យមភាគអតិប្បរមា*0.8 | D33: B | E33: ល្អណាស់
B34: មធ្យមភាគអតិប្បរមា*0.7 | D34: C | E34: ល្អ
B35: មធ្យមភាគអតិប្បរមា*0.6 | D35: D | E35: ល្អបង្គួ
B36: មធ្យមភាគអតិប្បរមា*0.5 | D36: E | E36: មធ្យម
B37: <មធ្យមភាគអតិប្បរមា*0.5 | D37: F | E37: ខ្សោយ
B38: *** NA គឺសិស្សមិនបានប្រទ្បងសូម្បី១មុខវិជ្ជា ពិន្ទុសរុបស្មើសូន្យ។
A39: សរុបលទ្ធផលតាមនិទ្ទេស | F39: សរុប | G39: ស្រី
B40: សិស្សសរុប | D40: សិស្សបានប្រទ្បង | F40: =D43+F43 -> 8 | G40: =E43+G43 -> 6 | H40: និទ្ទេស | T40: ផ្សេងៗ
...

Sheet អគ្គិសនី១
A1: ព្រះរាជាណាចក្រកម្ពុជា
A2: ជាតិ សាសនា ព្រះមហាក្សត្រ
A3: 6
A4: ក្រសួងអប់រំ យុវជន និងកីឡា | U4: ឧបសម្ព័ន្ធទី២
A5: =ស្ថិតិលទ្ធផលសិក្សាតាមនិទ្ទេស!A5 -> មន្ទីរអប់រំ យុវជន និងកីឡា ខេត្តបន្ទាយមានជ័យ
A6: =ស្ថិតិលទ្ធផលសិក្សាតាមនិទ្ទេស!A6 -> វិទ្យាល័យចំណេះទូទៅនិងបច្ចេកទេស ឯកជនដុនបូស្កូប៉ោយប៉ែត
A7: តារាងពិន្ទុប្រឡងប្រចាំខែមីនា របស់សិស្សផ្នែក អគ្គិសនី ឆ្នាំទី១
A8: =មេកានិច១!A8 -> ឆ្នាំសិក្សា ២០២៥- ២០២៦
A9: ល.រ | B9: គោត្តនាម | C9: និងនាម | D9: ភេទ | E9: ថ្ងៃខែឆ្នាំកំណើត | Q9: សរុប | R9: មធ្យមភាគ | S9: និទ្ទេស | T9: ចំណាត់ថ្នាក់ | U9: អវត្តមាន
G10: ខ្មែរ | H10: គណិត | I10: រូបវិទ្យា | J10: អង់គ្លេស | K10: ពលរដ្ឋ | L10: កីឡា | M10: ទ្រឹស្ដីទី១ | N10: ទ្រឹស្ដីទី២ | O10: ផ្ទាល់មាត់ | P10: អនុវត្ត
U11: មានច្បាប់ | V11: អត់ច្បាប់ | W11: សរុប
A12: 1 | B12: កែ | C12: សុពីន | D12: ប | E12: ១១ កញ្ញា ២០០៨ | G12: 0 | H12: 0 | I12: 0 | J12: 0 | K12: 0 | L12: 0 | M12: 0 | N12: 0 | O12: 0 | P12: 0 | Q12: =SUM(G12:P12)-W12 -> 0 | R12: =Q12/14.5 -> 0 | S12: =IF(R12>=50*0.9,"A",IF(R12>=50*0.8,"B",IF(R12>=50*0.7,"C",IF(R12>=50*0.6,"D",IF(R12>=50*0.5,"E",IF(Q12=0,"NA","F")))))) -> NA | T12: =RANK(R12,$R$12:$R$33) -> 22 | U12: 0 | V12: 0 | W12: =SUM(U12:V12) -> 0
A13: 2 | B13: ង៉ា | C13: ចាន់សុខងីម | D13: ស | E13: ៣១ ឧសភា ២០១០ | G13: 45 | H13: 38 | I13: 36 | J13: 33 | K13: 22 | L13: 20 | M13: 88 | N13: 81 | O13: 92 | P13: 100 | Q13: =SUM(G13:P13)-W13 -> 555 | R13: =Q13/14.5 -> 38.275862 | S13: =IF(R13>=50*0.9,"A",IF(R13>=50*0.8,"B",IF(R13>=50*0.7,"C",IF(R13>=50*0.6,"D",IF(R13>=50*0.5,"E",IF(Q13=0,"NA","F")))))) -> C | T13: =RANK(R13,$R$12:$R$33) -> 1 | U13: 0 | V13: 0 | W13: =SUM(U13:V13) -> 0
A14: 3 | B14: ចាន់ | C14: វិជ្ជា | D14: ប | E14: ២៩ មិនា ២០១០ | G14: 20 | H14: 1 | I14: 15 | J14: 25 | K14: 25 | L14: 20 | M14: 50 | N14: 30 | O14: 87 | P14: 100 | Q14: =SUM(G14:P14)-W14 -> 373 | R14: =Q14/14.5 -> 25.724138 | S14: =IF(R14>=50*0.9,"A",IF(R14>=50*0.8,"B",IF(R14>=50*0.7,"C",IF(R14>=50*0.6,"D",IF(R14>=50*0.5,"E",IF(Q14=0,"NA","F")))))) -> E | T14: =RANK(R14,$R$12:$R$33) -> 17 | U14: 0 | V14: 0 | W14: =SUM(U14:V14) -> 0
A15: 4 | B15: ជា | C15: សារ៉ា | D15: ស | E15: ០៧ សីហា ២០០៨ | G15: 41 | H15: 45 | I15: 17 | J15: 30 | K15: 24 | L15: 20 | M15: 51 | N15: 40 | O15: 55 | P15: 100 | Q15: =SUM(G15:P15)-W15 -> 423 | R15: =Q15/14.5 -> 29.172414 | S15: =IF(R15>=50*0.9,"A",IF(R15>=50*0.8,"B",IF(R15>=50*0.7,"C",IF(R15>=50*0.6,"D",IF(R15>=50*0.5,"E",IF(Q15=0,"NA","F")))))) -> E | T15: =RANK(R15,$R$12:$R$33) -> 11 | U15: 0 | V15: 0 | W15: =SUM(U15:V15) -> 0
A16: 5 | B16: ជី | C16: ណាំថាន | D16: ស | E16: ១៣ តុលា ២០១០ | G16: 66 | H16: 10 | I16: 26 | J16: 15 | K16: 25 | L16: 20 | M16: 54 | N16: 50 | O16: 79 | P16: 100 | Q16: =SUM(G16:P16)-W16 -> 445 | R16: =Q16/14.5 -> 30.689655 | S16: =IF(R16>=50*0.9,"A",IF(R16>=50*0.8,"B",IF(R16>=50*0.7,"C",IF(R16>=50*0.6,"D",IF(R16>=50*0.5,"E",IF(Q16=0,"NA","F")))))) -> D | T16: =RANK(R16,$R$12:$R$33) -> 9 | U16: 0 | V16: 0 | W16: =SUM(U16:V16) -> 0
A17: 6 | B17: ឈួន | C17: ពិសិទ្ធ | D17: ប | E17: ០៦ កុម្ភៈ ២០០៩ | G17: 25 | H17: 2 | I17: 34 | J17: 41 | K17: 25 | L17: 20 | M17: 75 | N17: 85 | O17: 90 | P17: 100 | Q17: =SUM(G17:P17)-W17 -> 497 | R17: =Q17/14.5 -> 34.275862 | S17: =IF(R17>=50*0.9,"A",IF(R17>=50*0.8,"B",IF(R17>=50*0.7,"C",IF(R17>=50*0.6,"D",IF(R17>=50*0.5,"E",IF(Q17=0,"NA","F")))))) -> D | T17: =RANK(R17,$R$12:$R$33) -> 5 | U17: 0 | V17: 0 | W17: =SUM(U17:V17) -> 0
A18: 7 | B18: ឈេន | C18: ឌីយ៉ា | D18: ប | E18: ២៩ កក្កដា ២០១០ | G18: 35 | H18: 2 | I18: 15 | J18: 37 | K18: 23 | L18: 20 | M18: 59 | N18: 50 | O18: 80 | P18: 100 | Q18: =SUM(G18:P18)-W18 -> 421 | R18: =Q18/14.5 -> 29.034483 | S18: =IF(R18>=50*0.9,"A",IF(R18>=50*0.8,"B",IF(R18>=50*0.7,"C",IF(R18>=50*0.6,"D",IF(R18>=50*0.5,"E",IF(Q18=0,"NA","F")))))) -> E | T18: =RANK(R18,$R$12:$R$33) -> 12 | U18: 0 | V18: 0 | W18: =SUM(U18:V18) -> 0
A19: 8 | B19: ដែន | C19: សុភ័ស្ដ | D19: ប | E19: ០៤ ឧសភា ២០០៨ | G19: 30 | H19: 10 | I19: 22 | J19: 23 | K19: 24 | L19: 20 | M19: 71 | N19: 81 | O19: 85 | P19: 100 | Q19: =SUM(G19:P19)-W19 -> 466 | R19: =Q19/14.5 -> 32.137931 | S19: =IF(R19>=50*0.9,"A",IF(R19>=50*0.8,"B",IF(R19>=50*0.7,"C",IF(R19>=50*0.6,"D",IF(R19>=50*0.5,"E",IF(Q19=0,"NA","F")))))) -> D | T19: =RANK(R19,$R$12:$R$33) -> 7 | U19: 0 | V19: 0 | W19: =SUM(U19:V19) -> 0
A20: 9 | B20: ឌីម | C20: អេនឌី | D20: ប | E20: 40284 | G20: 25 | H20: 18 | I20: 22 | J20: 22 | K20: 25 | L20: 20 | M20: 71 | N20: 81 | O20: 30 | P20: 70 | Q20: =SUM(G20:P20)-W20 -> 384 | R20: =Q20/14.5 -> 26.482759 | S20: =IF(R20>=50*0.9,"A",IF(R20>=50*0.8,"B",IF(R20>=50*0.7,"C",IF(R20>=50*0.6,"D",IF(R20>=50*0.5,"E",IF(Q20=0,"NA","F")))))) -> E | T20: =RANK(R20,$R$12:$R$33) -> 16 | U20: 0 | V20: 0 | W20: =SUM(U20:V20) -> 0
A21: 10 | B21: ណាត | C21: រ៉ានុត | D21: ប | E21: ១៤ វិច្ឆិកា ២០០៩ | G21: 25 | H21: 14 | I21: 18 | J21: 28 | K21: 24 | L21: 20 | M21: 31 | N21: 50 | O21: 60 | P21: 100 | Q21: =SUM(G21:P21)-W21 -> 364 | R21: =Q21/14.5 -> 25.103448 | S21: =IF(R21>=50*0.9,"A",IF(R21>=50*0.8,"B",IF(R21>=50*0.7,"C",IF(R21>=50*0.6,"D",IF(R21>=50*0.5,"E",IF(Q21=0,"NA","F")))))) -> E | T21: =RANK(R21,$R$12:$R$33) -> 20 | U21: 4 | V21: 2 | W21: =SUM(U21:V21) -> 6
A22: 11 | B22: ណុប | C22: ឌី | D22: ប | E22: 40430 | G22: 40 | H22: 2 | I22: 18 | J22: 43 | K22: 25 | L22: 20 | M22: 70 | N22: 50 | O22: 30 | P22: 70 | Q22: =SUM(G22:P22)-W22 -> 368 | R22: =Q22/14.5 -> 25.37931 | S22: =IF(R22>=50*0.9,"A",IF(R22>=50*0.8,"B",IF(R22>=50*0.7,"C",IF(R22>=50*0.6,"D",IF(R22>=50*0.5,"E",IF(Q22=0,"NA","F")))))) -> E | T22: =RANK(R22,$R$12:$R$33) -> 19 | U22: 0 | V22: 0 | W22: =SUM(U22:V22) -> 0
A23: 12 | B23: បុត្រ | C23: លីហួរ | D23: ប | E23: ២៨ មករា ២០១០ | G23: 10 | H23: 18 | I23: 10 | J23: 30 | K23: 24 | L23: 20 | M23: 48 | N23: 50 | O23: 60 | P23: 100 | Q23: =SUM(G23:P23)-W23 -> 364 | R23: =Q23/14.5 -> 25.103448 | S23: =IF(R23>=50*0.9,"A",IF(R23>=50*0.8,"B",IF(R23>=50*0.7,"C",IF(R23>=50*0.6,"D",IF(R23>=50*0.5,"E",IF(Q23=0,"NA","F")))))) -> E | T23: =RANK(R23,$R$12:$R$33) -> 20 | U23: 4 | V23: 2 | W23: =SUM(U23:V23) -> 6
A24: 13 | B24: ភា | C24: សុផាន់ណា | D24: ស | E24: ២០ ធ្នូ ២០០៩ | G24: 40 | H24: 38 | I24: 39 | J24: 40 | K24: 24 | L24: 20 | M24: 79 | N24: 60 | O24: 80 | P24: 100 | Q24: =SUM(G24:P24)-W24 -> 520 | R24: =Q24/14.5 -> 35.862069 | S24: =IF(R24>=50*0.9,"A",IF(R24>=50*0.8,"B",IF(R24>=50*0.7,"C",IF(R24>=50*0.6,"D",IF(R24>=50*0.5,"E",IF(Q24=0,"NA","F")))))) -> C | T24: =RANK(R24,$R$12:$R$33) -> 3 | U24: 0 | V24: 0 | W24: =SUM(U24:V24) -> 0
A25: 14 | B25: ម៉ៅ | C25: វិបុល | D25: ប | E25: ០១ មិថុនា ២០១០ | G25: 25 | H25: 7 | I25: 24 | J25: 22 | K25: 20 | L25: 20 | M25: 52 | N25: 53 | O25: 75 | P25: 100 | Q25: =SUM(G25:P25)-W25 -> 396 | R25: =Q25/14.5 -> 27.310345 | S25: =IF(R25>=50*0.9,"A",IF(R25>=50*0.8,"B",IF(R25>=50*0.7,"C",IF(R25>=50*0.6,"D",IF(R25>=50*0.5,"E",IF(Q25=0,"NA","F")))))) -> E | T25: =RANK(R25,$R$12:$R$33) -> 14 | U25: 2 | V25: 0 | W25: =SUM(U25:V25) -> 2
A26: 15 | B26: រៀ | C26: ឆេង | D26: ប | E26: ០៦ កញ្ញា ២០០៩ | G26: 41 | H26: 38 | I26: 33 | J26: 40 | K26: 25 | L26: 20 | M26: 78 | N26: 81 | O26: 85 | P26: 100 | Q26: =SUM(G26:P26)-W26 -> 541 | R26: =Q26/14.5 -> 37.310345 | S26: =IF(R26>=50*0.9,"A",IF(R26>=50*0.8,"B",IF(R26>=50*0.7,"C",IF(R26>=50*0.6,"D",IF(R26>=50*0.5,"E",IF(Q26=0,"NA","F")))))) -> C | T26: =RANK(R26,$R$12:$R$33) -> 2 | U26: 0 | V26: 0 | W26: =SUM(U26:V26) -> 0
A27: 16 | B27: សយ | C27: សារ៉ាត់ | D27: ប | E27: ០៨ មករា ២០១០ | G27: 26 | H27: 16 | I27: 21 | J27: 44 | K27: 24 | L27: 20 | M27: 62 | N27: 78 | O27: 90 | P27: 100 | Q27: =SUM(G27:P27)-W27 -> 481 | R27: =Q27/14.5 -> 33.172414 | S27: =IF(R27>=50*0.9,"A",IF(R27>=50*0.8,"B",IF(R27>=50*0.7,"C",IF(R27>=50*0.6,"D",IF(R27>=50*0.5,"E",IF(Q27=0,"NA","F")))))) -> D | T27: =RANK(R27,$R$12:$R$33) -> 6 | U27: 0 | V27: 0 | W27: =SUM(U27:V27) -> 0
A28: 17 | B28: សល់ | C28: មករា | D28: ប | E28: ២៩ ធ្នូ ២០០៧ | G28: 40 | H28: 2 | I28: 18 | J28: 41 | K28: 23 | L28: 20 | M28: 58 | N28: 53 | O28: 90 | P28: 100 | Q28: =SUM(G28:P28)-W28 -> 441 | R28: =Q28/14.5 -> 30.413793 | S28: =IF(R28>=50*0.9,"A",IF(R28>=50*0.8,"B",IF(R28>=50*0.7,"C",IF(R28>=50*0.6,"D",IF(R28>=50*0.5,"E",IF(Q28=0,"NA","F")))))) -> D | T28: =RANK(R28,$R$12:$R$33) -> 10 | U28: 4 | V28: 0 | W28: =SUM(U28:V28) -> 4
A29: 18 | B29: សល់ | C29: គឺមឡេង | D29: ស | E29: ២២ កក្កដា ២០១០ | G29: 39 | H29: 35 | I29: 27 | J29: 43 | K29: 24 | L29: 20 | M29: 50 | N29: 40 | O29: 75 | P29: 100 | Q29: =SUM(G29:P29)-W29 -> 450 | R29: =Q29/14.5 -> 31.034483 | S29: =IF(R29>=50*0.9,"A",IF(R29>=50*0.8,"B",IF(R29>=50*0.7,"C",IF(R29>=50*0.6,"D",IF(R29>=50*0.5,"E",IF(Q29=0,"NA","F")))))) -> D | T29: =RANK(R29,$R$12:$R$33) -> 8 | U29: 3 | V29: 0 | W29: =SUM(U29:V29) -> 3
A30: 19 | B30: សារ៉េត | C30: ម៉ាថាយ | D30: ប | E30: ០៧ កក្កដា ២០០៩ | G30: 24 | H30: 7 | I30: 18 | J30: 42 | K30: 25 | L30: 20 | M30: 54 | N30: 30 | O30: 50 | P30: 100 | Q30: =SUM(G30:P30)-W30 -> 370 | R30: =Q30/14.5 -> 25.517241 | S30: =IF(R30>=50*0.9,"A",IF(R30>=50*0.8,"B",IF(R30>=50*0.7,"C",IF(R30>=50*0.6,"D",IF(R30>=50*0.5,"E",IF(Q30=0,"NA","F")))))) -> E | T30: =RANK(R30,$R$12:$R$33) -> 18 | U30: 0 | V30: 0 | W30: =SUM(U30:V30) -> 0
A31: 20 | B31: សុខ | C31: ដាក់ហ៊ាង | D31: ប | E31: ១៦ មិថុនា ២០១១ | G31: 30 | H31: 23 | I31: 19 | J31: 36 | K31: 23 | L31: 20 | M31: 51 | N31: 30 | O31: 55 | P31: 100 | Q31: =SUM(G31:P31)-W31 -> 387 | R31: =Q31/14.5 -> 26.689655 | S31: =IF(R31>=50*0.9,"A",IF(R31>=50*0.8,"B",IF(R31>=50*0.7,"C",IF(R31>=50*0.6,"D",IF(R31>=50*0.5,"E",IF(Q31=0,"NA","F")))))) -> E | T31: =RANK(R31,$R$12:$R$33) -> 15 | U31: 0 | V31: 0 | W31: =SUM(U31:V31) -> 0
A32: 21 | B32: សុខ | C32: ដាវិត | D32: ប | E32: ០១ ធ្នូ ២០០៨ | G32: 46 | H32: 38 | I32: 32 | J32: 18 | K32: 25 | L32: 20 | M32: 70 | N32: 77 | O32: 80 | P32: 100 | Q32: =SUM(G32:P32)-W32 -> 506 | R32: =Q32/14.5 -> 34.896552 | S32: =IF(R32>=50*0.9,"A",IF(R32>=50*0.8,"B",IF(R32>=50*0.7,"C",IF(R32>=50*0.6,"D",IF(R32>=50*0.5,"E",IF(Q32=0,"NA","F")))))) -> D | T32: =RANK(R32,$R$12:$R$33) -> 4 | U32: 0 | V32: 0 | W32: =SUM(U32:V32) -> 0
A33: 22 | B33: ហ៊ន | C33: សុខហ៊ីន | D33: ប | E33: ១៣ កញ្ញា ២០១០ | G33: 14 | H33: 2 | I33: 15 | J33: 50 | K33: 23 | L33: 20 | M33: 58 | N33: 50 | O33: 70 | P33: 100 | Q33: =SUM(G33:P33)-W33 -> 402 | R33: =Q33/14.5 -> 27.724138 | S33: =IF(R33>=50*0.9,"A",IF(R33>=50*0.8,"B",IF(R33>=50*0.7,"C",IF(R33>=50*0.6,"D",IF(R33>=50*0.5,"E",IF(Q33=0,"NA","F")))))) -> E | T33: =RANK(R33,$R$12:$R$33) -> 13 | U33: 0 | V33: 0 | W33: =SUM(U33:V33) -> 0
A34: ="បញ្ឈប់បញ្ជីត្រឹមឈ្មោះ ហ៊ន សុខហ៊ីន "&" ចំនួនសរុប "&COUNT(A12:A33)&" នាក់"&" ក្នុងនោះស្រី "&COUNTIF(D12:D33,"ស")&" នាក់ ។" -> បញ្ឈប់បញ្ជីត្រឹមឈ្មោះ ហ៊ន សុខហ៊ីន ចំនួនសរុប 22 នាក់ ក្នុងនោះស្រី 5 នាក់ ។
B35: * បញ្ជាក់
B36: មធ្យមភាគអតិប្បរមា*0.9 | D36: A | E36: ល្អប្រសើរ
B37: មធ្យមភាគអតិប្បរមា*0.8 | D37: B | E37: ល្អណាស់
B38: មធ្យមភាគអតិប្បរមា*0.7 | D38: C | E38: ល្អ
B39: មធ្យមភាគអតិប្បរមា*0.6 | D39: D | E39: ល្អបង្គួ
B40: មធ្យមភាគអតិប្បរមា*0.5 | D40: E | E40: មធ្យម
...

Sheet កុំព្យទ័រ១
A1: ព្រះរាជាណាចក្រកម្ពុជា
A2: ជាតិ សាសនា ព្រះមហាក្សត្រ
A3: 6
A4: ក្រសួងអប់រំ យុវជន និងកីឡា | U4: ឧបសម្ព័ន្ធទី២
A5: =ស្ថិតិលទ្ធផលសិក្សាតាមនិទ្ទេស!A5 -> មន្ទីរអប់រំ យុវជន និងកីឡា ខេត្តបន្ទាយមានជ័យ
A6: =ស្ថិតិលទ្ធផលសិក្សាតាមនិទ្ទេស!A6 -> វិទ្យាល័យចំណេះទូទៅនិងបច្ចេកទេស ឯកជនដុនបូស្កូប៉ោយប៉ែត
A7: តារាងពិន្ទុប្រឡងប្រចាំខែមីនា របស់សិស្សផ្នែក​ កំព្យូទ័រ​ ឆ្នាំទី១
A8: =មេកានិច១!A8 -> ឆ្នាំសិក្សា ២០២៥- ២០២៦
A9: ល.រ | B9: គោត្តនាម | C9: និងនាម | D9: ភេទ | E9: ថ្ងៃខែឆ្នាំកំណើត | G9: មុខវិជ្ជា | Q9: សរុប | R9: មធ្យមភាគ | S9: និទ្ទេស | T9: ចំណាត់ថ្នាក់ | U9: អវត្តមាន
G10: ខ្មែរ | H10: គណិត | I10: រូប​ | J10: អង់គ្លេស | K10: ពលរដ្ឋ | L10: កីឡា | M10: ទ្រឹស្ដីទី១ | N10: ទ្រឹស្ដីទី២ | O10: ផ្ទាល់មាត់ | P10: អនុវត្ត
U11: មានច្បាប់ | V11: អត់ច្បាប់ | W11: សរុប
A12: 1 | B12: កែ | C12: សុនីសា | D12: ស | E12: ២៣ កុម្ភៈ ២០១០ | G12: 46 | H12: 18 | I12: 42 | J12: 34 | K12: 23 | L12: 20 | M12: 96 | N12: 74 | O12: 78 | P12: 95 | Q12: =SUM(G12:P12)-W12 -> 525 | R12: =Q12/13.5 -> 38.888889 | S12: =IF(R12>=50*0.9,"A",IF(R12>=50*0.8,"B",IF(R12>=50*0.7,"C",IF(R12>=50*0.6,"D",IF(R12>=50*0.5,"E",IF(Q12=0,"NA","F")))))) -> C | T12: =RANK(R12,$R$12:$R$40) -> 11 | U12: 1 | V12: 0 | W12: =SUM(U12:V12) -> 1
A13: 2 | B13: ខេន | C13: នរៈបុត្ត | D13: ប | E13: ១៤ កុម្ភៈ ២០០៨ | G13: 47 | H13: 26 | I13: 26 | J13: 21 | K13: 24 | L13: 20 | M13: 82 | N13: 73 | O13: 70 | P13: 100 | Q13: =SUM(G13:P13)-W13 -> 481 | R13: =Q13/13.5 -> 35.62963 | S13: =IF(R13>=50*0.9,"A",IF(R13>=50*0.8,"B",IF(R13>=50*0.7,"C",IF(R13>=50*0.6,"D",IF(R13>=50*0.5,"E",IF(Q13=0,"NA","F")))))) -> C | T13: =RANK(R13,$R$12:$R$40) -> 17 | U13: 6 | V13: 2 | W13: =SUM(U13:V13) -> 8
A14: 3 | B14: ខែង | C14: សុខនី | D14: ស | E14: ២៨ ធ្នូ ២០១០ | G14: 61 | H14: 13 | I14: 41 | J14: 27 | K14: 25 | L14: 20 | M14: 74 | N14: 87 | O14: 88 | P14: 101 | Q14: =SUM(G14:P14)-W14 -> 537 | R14: =Q14/13.5 -> 39.777778 | S14: =IF(R14>=50*0.9,"A",IF(R14>=50*0.8,"B",IF(R14>=50*0.7,"C",IF(R14>=50*0.6,"D",IF(R14>=50*0.5,"E",IF(Q14=0,"NA","F")))))) -> C | T14: =RANK(R14,$R$12:$R$40) -> 9 | U14: 0 | V14: 0 | W14: =SUM(U14:V14) -> 0
A15: 4 | B15: គុណ | C15: មិនា | D15: ស | E15: ២០ សីហា ២០១០ | G15: 39 | H15: 38 | I15: 25 | J15: 46 | K15: 23 | L15: 20 | M15: 93 | N15: 83 | O15: 85 | P15: 109 | Q15: =SUM(G15:P15)-W15 -> 559 | R15: =Q15/13.5 -> 41.407407 | S15: =IF(R15>=50*0.9,"A",IF(R15>=50*0.8,"B",IF(R15>=50*0.7,"C",IF(R15>=50*0.6,"D",IF(R15>=50*0.5,"E",IF(Q15=0,"NA","F")))))) -> B | T15: =RANK(R15,$R$12:$R$40) -> 6 | U15: 2 | V15: 0 | W15: =SUM(U15:V15) -> 2
A16: 5 | B16: ឃួន | C16: សុខលាភ | D16: ប | E16: ២១ មករា ២០១១ | G16: 42 | H16: 38 | I16: 26 | J16: 41 | K16: 23 | L16: 20 | M16: 61 | N16: 72 | O16: 82 | P16: 100 | Q16: =SUM(G16:P16)-W16 -> 500 | R16: =Q16/13.5 -> 37.037037 | S16: =IF(R16>=50*0.9,"A",IF(R16>=50*0.8,"B",IF(R16>=50*0.7,"C",IF(R16>=50*0.6,"D",IF(R16>=50*0.5,"E",IF(Q16=0,"NA","F")))))) -> C | T16: =RANK(R16,$R$12:$R$40) -> 14 | U16: 2 | V16: 3 | W16: =SUM(U16:V16) -> 5
A17: 6 | B17: ជា | C17: គឹមលាង | D17: ស | E17: ១៥ ឧសភា ២០១១ | G17: 65 | H17: 18 | I17: 28 | J17: 3 | K17: 25 | L17: 20 | M17: 97 | N17: 72 | O17: 88 | P17: 100 | Q17: =SUM(G17:P17)-W17 -> 516 | R17: =Q17/13.5 -> 38.222222 | S17: =IF(R17>=50*0.9,"A",IF(R17>=50*0.8,"B",IF(R17>=50*0.7,"C",IF(R17>=50*0.6,"D",IF(R17>=50*0.5,"E",IF(Q17=0,"NA","F")))))) -> C | T17: =RANK(R17,$R$12:$R$40) -> 12 | U17: 0 | V17: 0 | W17: =SUM(U17:V17) -> 0
A18: 7 | B18: ធៀង | C18: លីសា | D18: ស | E18: ២៨ កញ្ញា ២០០៩ | G18: 53 | H18: 13 | I18: 25 | J18: 18 | K18: 24 | L18: 20 | M18: 67 | N18: 50 | O18: 60 | P18: 78 | Q18: =SUM(G18:P18)-W18 -> 407 | R18: =Q18/13.5 -> 30.148148 | S18: =IF(R18>=50*0.9,"A",IF(R18>=50*0.8,"B",IF(R18>=50*0.7,"C",IF(R18>=50*0.6,"D",IF(R18>=50*0.5,"E",IF(Q18=0,"NA","F")))))) -> D | T18: =RANK(R18,$R$12:$R$40) -> 26 | U18: 1 | V18: 0 | W18: =SUM(U18:V18) -> 1
A19: 8 | B19: ធឿង | C19: គឹមប៉ាលី | D19: ស | E19: ២២ មេសា ២០១១ | G19: 50 | H19: 18 | I19: 25 | J19: 3 | K19: 25 | L19: 20 | M19: 71 | N19: 56 | O19: 75 | P19: 88 | Q19: =SUM(G19:P19)-W19 -> 431 | R19: =Q19/13.5 -> 31.925926 | S19: =IF(R19>=50*0.9,"A",IF(R19>=50*0.8,"B",IF(R19>=50*0.7,"C",IF(R19>=50*0.6,"D",IF(R19>=50*0.5,"E",IF(Q19=0,"NA","F")))))) -> D | T19: =RANK(R19,$R$12:$R$40) -> 24 | U19: 0 | V19: 0 | W19: =SUM(U19:V19) -> 0
A20: 9 | B20: នឿន | C20: វ៉ាន់លីហ្សា | D20: ស | E20: ១៧ កញ្ញា ២០១១ | G20: 55 | H20: 18 | I20: 36 | J20: 45 | K20: 25 | L20: 20 | M20: 94 | N20: 82 | O20: 84 | P20: 88 | Q20: =SUM(G20:P20)-W20 -> 543 | R20: =Q20/13.5 -> 40.222222 | S20: =IF(R20>=50*0.9,"A",IF(R20>=50*0.8,"B",IF(R20>=50*0.7,"C",IF(R20>=50*0.6,"D",IF(R20>=50*0.5,"E",IF(Q20=0,"NA","F")))))) -> B | T20: =RANK(R20,$R$12:$R$40) -> 8 | U20: 4 | V20: 0 | W20: =SUM(U20:V20) -> 4
A21: 10 | B21: ប្រាក់ | C21: គីតិច | D21: ប | E21: ០៦ សីហា ២០០៩ | G21: 67 | H21: 45 | I21: 28 | J21: 43 | K21: 25 | L21: 20 | M21: 50 | N21: 98 | O21: 100 | P21: 98 | Q21: =SUM(G21:P21)-W21 -> 568 | R21: =Q21/13.5 -> 42.074074 | S21: =IF(R21>=50*0.9,"A",IF(R21>=50*0.8,"B",IF(R21>=50*0.7,"C",IF(R21>=50*0.6,"D",IF(R21>=50*0.5,"E",IF(Q21=0,"NA","F")))))) -> B | T21: =RANK(R21,$R$12:$R$40) -> 4 | U21: 6 | V21: 0 | W21: =SUM(U21:V21) -> 6
A22: 11 | B22: ពួន | C22: ដាឡែន | D22: ស | E22: ០៦ ធ្នូ ២០០៩ | G22: 25 | H22: 2 | I22: 33 | J22: 21 | K22: 22 | L22: 20 | M22: 89 | N22: 46 | O22: 86 | P22: 92 | Q22: =SUM(G22:P22)-W22 -> 432 | R22: =Q22/13.5 -> 32 | S22: =IF(R22>=50*0.9,"A",IF(R22>=50*0.8,"B",IF(R22>=50*0.7,"C",IF(R22>=50*0.6,"D",IF(R22>=50*0.5,"E",IF(Q22=0,"NA","F")))))) -> D | T22: =RANK(R22,$R$12:$R$40) -> 23 | U22: 4 | V22: 0 | W22: =SUM(U22:V22) -> 4
A23: 12 | B23: ភារុណ | C23: ថេយុន | D23: ប | E23: ០៤ កញ្ញា ២០១១ | G23: 41 | H23: 38 | I23: 20 | J23: 34 | K23: 24 | L23: 20 | M23: 65 | N23: 64 | O23: 70 | P23: 92 | Q23: =SUM(G23:P23)-W23 -> 468 | R23: =Q23/13.5 -> 34.666667 | S23: =IF(R23>=50*0.9,"A",IF(R23>=50*0.8,"B",IF(R23>=50*0.7,"C",IF(R23>=50*0.6,"D",IF(R23>=50*0.5,"E",IF(Q23=0,"NA","F")))))) -> D | T23: =RANK(R23,$R$12:$R$40) -> 20 | U23: 0 | V23: 0 | W23: =SUM(U23:V23) -> 0
... A40: 29 | B40: ហ៊ីម | C40: ធានី | D40: ស | E40: ០៧ ឧសភា ២០១០ | G40: 44 | H40: 2 | I40: 25 | J40: 15 | K40: 22 | L40: 20 | M40: 72 | N40: 59 | O40: 84 | P40: 99 | Q40: =SUM(G40:P40)-W40 -> 441 | R40: =Q40/13.5 -> 32.666667 | S40: =IF(R40>=50*0.9,"A",IF(R40>=50*0.8,"B",IF(R40>=50*0.7,"C",IF(R40>=50*0.6,"D",IF(R40>=50*0.5,"E",IF(Q40=0,"NA","F")))))) -> D | T40: =RANK(R40,$R$12:$R$40) -> 22 | U40: 1 | V40: 0 | W40: =SUM(U40:V40) -> 1
A41: ="បញ្ឈប់បញ្ជីត្រឹមឈ្មោះ ហ៊ឹម ធានី "&" ចំនួនសរុប "&COUNT(A12:A40)&" នាក់"&" ក្នុងនោះស្រី "&COUNTIF(D12:D40,"ស")&" នាក់ ។" -> បញ្ឈប់បញ្ជីត្រឹមឈ្មោះ ហ៊ឹម ធានី ចំនួនសរុប 29 នាក់ ក្នុងនោះស្រី 20 នាក់ ។
B42: * បញ្ជាក់ | N42: ​
A43: លំដាប់ពិន្ទុ | D43: និទ្ទេស | E43: សេចក្តីពណ៌នា
A44: មធ្យមភាគអតិប្បរមា*0.9 | D44: A | E44: ល្អប្រសើរ
A45: មធ្យមភាគអតិប្បរមា*0.8 | D45: B | E45: ល្អណាស់
A46: មធ្យមភាគអតិប្បរមា*0.7 | D46: C | E46: ល្អ
A47: មធ្យមភាគអតិប្បរមា*0.6 | D47: D | E47: ល្អបង្គួ
A48: មធ្យមភាគអតិប្បរមា*0.5 | D48: E | E48: មធ្យម
A49: <មធ្យមភាគអតិប្បរមា*0.5 | D49: F | E49: ខ្សោយ
A50: *** NA គឺសិស្សមិនបានប្រទ្បងសូម្បី១មុខវិជ្ជា ពិន្ទុសរុបស្មើសូន្យ។
A51: សរុបលទ្ធផលតាមនិទ្ទេស | F51: សរុប | G51: ស្រី
B52: សិស្សសរុប | D52: សិស្សបានប្រទ្បង | F52: =D55+F55 -> 29 | G52: =E55+G55 -> 20 | H52: និទ្ទេស | T52: ផ្សេងៗ
D53: សិស្សប្រទ្បងជាប់ | F53: សិស្សប្រទ្បងធ្លាក់(F) | H53: A | J53: B | L53: C | N53: D | P53: E | R53: NA
B54: សរុប | C54: ស្រី | D54: សរុប | E54: ស្រី | F54: សរុប | G54: ស្រី | H54: សរុប | I54: ស្រី | J54: សរុប | K54: ស្រី | L54: សរុប | M54: ស្រី | N54: សរុប | O54: ស្រី | P54: សរុប | Q54: ស្រី | R54: សរុប | S54: ស្រី
B55: =COUNT(A12:A40) -> 29 | C55: =COUNTIF(D12:D40,"ស") -> 20 | D55: =SUM(H55,J55,L55,N55,P55) -> 29 | E55: =SUM(I55,K55,M55,O55,Q55) -> 20 | F55: =COUNTIF(S12:S40,"F") -> 0 | G55: =COUNTIFS(S12:S40,"F",D12:D40,"ស") -> 0 | H55: =COUNTIF(S12:S40,"A") -> 0 | I55: =COUNTIFS(S12:S40,"A",D12:D40,"ស") -> 0 | J55: =COUNTIF(S12:S40,"B") -> 8 | K55: =COUNTIFS(S12:S40,"B",D12:D40,"ស") -> 3 | L55: =COUNTIF(S12:S40,"C") -> 11 | M55: =COUNTIFS(S12:S40,"C",D12:D40,"ស") -> 8 | N55: =COUNTIF(S12:S40,"D") -> 7 | O55: =COUNTIFS(S12:S40,"D",D12:D40,"ស") -> 6 | P55: =COUNTIF(S12:S40,"E") -> 3 | Q55: =COUNTIFS(S12:S40,"E",D12:D40,"ស") -> 3 | R55: =COUNTIF(S12:S40,"NA") -> 0 | S55: =COUNTIFS(S12:S40,"NA",D12:D40,"ស") -> 0
P56: =កុំព្យទ័រ៣!P52 -> ថ្ងៃអង្គារ ១៣កើត ខែចេត្រ ឆ្នាំម្សាញ់ សប្តស័ក ព.ស ២៥៦៩
...

Sheet មេកានិច២
A1: ព្រះរាជាណាចក្រកម្ពុជា
A2: ជាតិ សាសនា ព្រះមហាក្សត្រ
A3: 6
A4: ក្រសួងអប់រំ យុវជន និងកីឡា | U4: ឧបសម្ព័ន្ធទី២
A5: =ស្ថិតិលទ្ធផលសិក្សាតាមនិទ្ទេស!A5 -> មន្ទីរអប់រំ យុវជន និងកីឡា ខេត្តបន្ទាយមានជ័យ
A6: =ស្ថិតិលទ្ធផលសិក្សាតាមនិទ្ទេស!A6 -> វិទ្យាល័យចំណេះទូទៅនិងបច្ចេកទេស ឯកជនដុនបូស្កូប៉ោយប៉ែត
A7: តារាងពិន្ទុប្រឡងប្រចាំខែមីនា របស់សិស្សផ្នែក មេកានិច ឆ្នាំទី២​
A8: =មេកានិច១!A8 -> ឆ្នាំសិក្សា ២០២៥- ២០២៦
A9: ល.រ | B9: គោត្តនាម | C9: និងនាម | D9: ភេទ | E9: ថ្ងៃខែឆ្នាំកំណើត | G9: មុខវិជ្ជា | Q9: សរុប | R9: មធ្យមភាគ | S9: និទ្ទេស | T9: ចំណាត់ថ្នាក់ | U9: អវត្តមាន
G10: ខ្មែរ | H10: គណិត | I10: រូប​ | J10: អង់គ្លេស | K10: ពលរដ្ឋ | L10: កីឡា | M10: ទ្រឹស្ដីទី១ | N10: ទ្រឹស្ដីទី២ | O10: ផ្ទាល់មាត់ | P10: អនុវត្ត
U11: មានច្បាប់ | V11: អត់ច្បាប់ | W11: សរុប
A12: 1 | B12: កុសល | C12: ស៊ីណា | D12: ស | E12: ០៣ តុលា ២០០៨ | G12: 45 | H12: 38 | I12: 27 | J12: 37 | K12: 22 | L12: 20 | M12: 75 | N12: 80 | O12: 93 | P12: 83 | Q12: =SUM(G12:P12)-W12 -> 520 | R12: =Q12/14.5 -> 35.862069 | S12: =IF(R12>=50*0.9,"A",IF(R12>=50*0.8,"B",IF(R12>=50*0.7,"C",IF(R12>=50*0.6,"D",IF(R12>=50*0.5,"E",IF(Q12=0,"NA","F")))))) -> C | T12: =RANK(R12,$R$12:$R$26) -> 4 | U12: 0 | V12: 0 | W12: =SUM(U12:V12) -> 0
A13: 2 | B13: ឈួង | C13: សេងហ៊ុយ | D13: ប | E13: ០៨ មករា ២០០៩ | G13: 40 | H13: 51 | I13: 28 | J13: 30 | K13: 24 | L13: 20 | M13: 40 | N13: 40 | O13: 75 | P13: 93 | Q13: =SUM(G13:P13)-W13 -> 440 | R13: =Q13/14.5 -> 30.344828 | S13: =IF(R13>=50*0.9,"A",IF(R13>=50*0.8,"B",IF(R13>=50*0.7,"C",IF(R13>=50*0.6,"D",IF(R13>=50*0.5,"E",IF(Q13=0,"NA","F")))))) -> D | T13: =RANK(R13,$R$12:$R$26) -> 9 | U13: 1 | V13: 0 | W13: =SUM(U13:V13) -> 1
A14: 3 | B14: ថា | C14: សំណាង | D14: ប | E14: ០៣ មេសា ២០០៥ | G14: 44 | H14: 51 | I14: 28 | J14: 35 | K14: 23 | L14: 20 | M14: 90 | N14: 95 | O14: 98 | P14: 115 | Q14: =SUM(G14:P14)-W14 -> 598 | R14: =Q14/14.5 -> 41.241379 | S14: =IF(R14>=50*0.9,"A",IF(R14>=50*0.8,"B",IF(R14>=50*0.7,"C",IF(R14>=50*0.6,"D",IF(R14>=50*0.5,"E",IF(Q14=0,"NA","F")))))) -> B | T14: =RANK(R14,$R$12:$R$26) -> 2 | U14: 1 | V14: 0 | W14: =SUM(U14:V14) -> 1
A15: 4 | B15: ថេ | C15: មិញ | D15: ប | E15: ២៣ កញ្ញា ២០០៨ | G15: 44 | H15: 64 | I15: 42 | J15: 27 | K15: 22 | L15: 20 | M15: 100 | N15: 100 | O15: 100 | P15: 125 | Q15: =SUM(G15:P15)-W15 -> 642 | R15: =Q15/14.5 -> 44.275862 | S15: =IF(R15>=50*0.9,"A",IF(R15>=50*0.8,"B",IF(R15>=50*0.7,"C",IF(R15>=50*0.6,"D",IF(R15>=50*0.5,"E",IF(Q15=0,"NA","F")))))) -> B | T15: =RANK(R15,$R$12:$R$26) -> 1 | U15: 2 | V15: 0 | W15: =SUM(U15:V15) -> 2
A16: 5 | B16: ទូច | C16: ស្រីមាស | D16: ស | E16: ២០ មករា ២០០៦ | G16: 49 | H16: 44 | I16: 27 | J16: 36 | K16: 25 | L16: 20 | M16: 35 | N16: 70 | O16: 43 | P16: 68 | Q16: =SUM(G16:P16)-W16 -> 415 | R16: =Q16/14.5 -> 28.62069 | S16: =IF(R16>=50*0.9,"A",IF(R16>=50*0.8,"B",IF(R16>=50*0.7,"C",IF(R16>=50*0.6,"D",IF(R16>=50*0.5,"E",IF(Q16=0,"NA","F")))))) -> E | T16: =RANK(R16,$R$12:$R$26) -> 11 | U16: 0 | V16: 2 | W16: =SUM(U16:V16) -> 2
A17: 6 | B17: ផេង | C17: ជូម៉ុង | D17: ប | E17: ០៤ មិនា ២០០៦ | G17: 38 | H17: 51 | I17: 20 | J17: 31 | K17: 24 | L17: 20 | M17: 30 | N17: 52 | O17: 50 | P17: 55 | Q17: =SUM(G17:P17)-W17 -> 363 | R17: =Q17/14.5 -> 25.034483 | S17: =IF(R17>=50*0.9,"A",IF(R17>=50*0.8,"B",IF(R17>=50*0.7,"C",IF(R17>=50*0.6,"D",IF(R17>=50*0.5,"E",IF(Q17=0,"NA","F")))))) -> E | T17: =RANK(R17,$R$12:$R$26) -> 14 | U17: 3 | V17: 5 | W17: =SUM(U17:V17) -> 8
A18: 7 | B18: ម៉ុះ | C18: សុខលាបភា | D18: ស | E18: ០៨ កុម្ភៈ ២០០៧ | G18: 51 | H18: 39 | I18: 26 | J18: 20 | K18: 24 | L18: 20 | M18: 75 | N18: 80 | O18: 88 | P18: 80 | Q18: =SUM(G18:P18)-W18 -> 503 | R18: =Q18/14.5 -> 34.689655 | S18: =IF(R18>=50*0.9,"A",IF(R18>=50*0.8,"B",IF(R18>=50*0.7,"C",IF(R18>=50*0.6,"D",IF(R18>=50*0.5,"E",IF(Q18=0,"NA","F")))))) -> D | T18: =RANK(R18,$R$12:$R$26) -> 5 | U18: 0 | V18: 0 | W18: =SUM(U18:V18) -> 0
A19: 8 | B19: លឺត | C19: ម៉េងសេង | D19: ប | E19: ០៨ កក្កដា ២០០៧ | G19: 39 | H19: 30 | I19: 24 | J19: 36 | K19: 22 | L19: 20 | M19: 70 | N19: 65 | O19: 40 | P19: 88 | Q19: =SUM(G19:P19)-W19 -> 433 | R19: =Q19/14.5 -> 29.862069 | S19: =IF(R19>=50*0.9,"A",IF(R19>=50*0.8,"B",IF(R19>=50*0.7,"C",IF(R19>=50*0.6,"D",IF(R19>=50*0.5,"E",IF(Q19=0,"NA","F")))))) -> E | T19: =RANK(R19,$R$12:$R$26) -> 10 | U19: 1 | V19: 0 | W19: =SUM(U19:V19) -> 1
A20: 9 | B20: លឺត | C20: ម៉េងសុង | D20: ប | E20: ១៨ ធ្នូ ២០០៩ | G20: 39 | H20: 44 | I20: 18 | J20: 27 | K20: 20 | L20: 20 | M20: 60 | N20: 55 | O20: 33 | P20: 65 | Q20: =SUM(G20:P20)-W20 -> 380 | R20: =Q20/14.5 -> 26.206897 | S20: =IF(R20>=50*0.9,"A",IF(R20>=50*0.8,"B",IF(R20>=50*0.7,"C",IF(R20>=50*0.6,"D",IF(R20>=50*0.5,"E",IF(Q20=0,"NA","F")))))) -> E | T20: =RANK(R20,$R$12:$R$26) -> 13 | U20: 1 | V20: 0 | W20: =SUM(U20:V20) -> 1
A21: 10 | B21: វែង | C21: ចាន់ធីតា | D21: ស | E21: ២១ កក្កដា ២០០៨ | G21: 50 | H21: 51 | I21: 39 | J21: 34 | K21: 22 | L21: 20 | M21: 80 | N21: 75 | O21: 83 | P21: 100 | Q21: =SUM(G21:P21)-W21 -> 554 | R21: =Q21/14.5 -> 38.206897 | S21: =IF(R21>=50*0.9,"A",IF(R21>=50*0.8,"B",IF(R21>=50*0.7,"C",IF(R21>=50*0.6,"D",IF(R21>=50*0.5,"E",IF(Q21=0,"NA","F")))))) -> C | T21: =RANK(R21,$R$12:$R$26) -> 3 | U21: 0 | V21: 0 | W21: =SUM(U21:V21) -> 0
A22: 11 | B22: រ៉ុម | C22: ណាត់ | D22: ប | E22: ១៩ មករា ២០០៩ | G22: 39 | H22: 51 | I22: 15 | J22: 42 | K22: 22 | L22: 20 | M22: 70 | N22: 70 | O22: 75 | P22: 83 | Q22: =SUM(G22:P22)-W22 -> 487 | R22: =Q22/14.5 -> 33.586207 | S22: =IF(R22>=50*0.9,"A",IF(R22>=50*0.8,"B",IF(R22>=50*0.7,"C",IF(R22>=50*0.6,"D",IF(R22>=50*0.5,"E",IF(Q22=0,"NA","F")))))) -> D | T22: =RANK(R22,$R$12:$R$26) -> 6 | U22: 0 | V22: 0 | W22: =SUM(U22:V22) -> 0
A23: 12 | B23: ហម | C23: សុខឡាយ | D23: ប | E23: ០៤ ឧសភា ២០០៦ | G23: 50 | H23: 51 | I23: 32 | J23: 31 | K23: 15 | L23: 20 | M23: 65 | N23: 70 | O23: 35 | P23: 95 | Q23: =SUM(G23:P23)-W23 -> 461 | R23: =Q23/14.5 -> 31.793103 | S23: =IF(R23>=50*0.9,"A",IF(R23>=50*0.8,"B",IF(R23>=50*0.7,"C",IF(R23>=50*0.6,"D",IF(R23>=50*0.5,"E",IF(Q23=0,"NA","F")))))) -> D | T23: =RANK(R23,$R$12:$R$26) -> 8 | U23: 3 | V23: 0 | W23: =SUM(U23:V23) -> 3
... A26: 15 | B26: ឡេង | C26: សុវណ្ណតារា | D26: ប | E26: ២៦ មិថុនា ២០០៨ | G26: 42 | H26: 49 | I26: 25 | J26: 39 | K26: 23 | L26: 20 | M26: 70 | N26: 70 | O26: 70 | P26: 78 | Q26: =SUM(G26:P26)-W26 -> 486 | R26: =Q26/14.5 -> 33.517241 | S26: =IF(R26>=50*0.9,"A",IF(R26>=50*0.8,"B",IF(R26>=50*0.7,"C",IF(R26>=50*0.6,"D",IF(R26>=50*0.5,"E",IF(Q26=0,"NA","F")))))) -> D | T26: =RANK(R26,$R$12:$R$26) -> 7 | U26: 0 | V26: 0 | W26: =SUM(U26:V26) -> 0
B27: ឡេង | C27: សុវណ្ណតារា | D27: ប | E27: ២៦ មិថុនា ២០០៨ | G27: 51 | H27: 38 | I27: 25 | K27: 17 | L27: 20 | M27: 83 | N27: 85 | O27: 78 | P27: 99 | U27: 0 | V27: 0 | W27: 0
L28: 20
L29: 20
L30: 20
L31: 20
L32: 20
A34: ="បញ្ឈប់បញ្ជីត្រឹមឈ្មោះ ឡេង សុវណ្ណតារា "&" ចំនួនសរុប "&COUNT(A12:A26)&" នាក់"&" ក្នុងនោះស្រី "&COUNTIF(D12:D26,"ស")&" នាក់ ។" -> បញ្ឈប់បញ្ជីត្រឹមឈ្មោះ ឡេង សុវណ្ណតារា ចំនួនសរុប 15 នាក់ ក្នុងនោះស្រី 5 នាក់ ។
B35: * បញ្ជាក់
B36: លំដាប់ពិន្ទុ | D36: និទ្ទេស | E36: សេចក្តីពណ៌នា
B37: មធ្យមភាគអតិប្បរមា*0.9 | D37: A | E37: ល្អប្រសើរ
B38: មធ្យមភាគអតិប្បរមា*0.8 | D38: B | E38: ល្អណាស់
B39: មធ្យមភាគអតិប្បរមា*0.7 | D39: C | E39: ល្អ
B40: មធ្យមភាគអតិប្បរមា*0.6 | D40: D | E40: ល្អបង្គួ
B41: មធ្យមភាគអតិប្បរមា*0.5 | D41: E | E41: មធ្យម
B42: <មធ្យមភាគអតិប្បរមា*0.5 | D42: F | E42: ខ្សោយ
B43: *** NA គឺសិស្សមិនបានប្រទ្បងសូម្បី១មុខវិជ្ជា ពិន្ទុសរុបស្មើសូន្យ។
...

Sheet អគ្គិសនី២
A1: ព្រះរាជាណាចក្រកម្ពុជា
A2: ជាតិ សាសនា ព្រះមហាក្សត្រ
A3: 6
A4: ក្រសួងអប់រំ យុវជន និងកីឡា | U4: ឧបសម្ព័ន្ធទី២
A5: =ស្ថិតិលទ្ធផលសិក្សាតាមនិទ្ទេស!A5 -> មន្ទីរអប់រំ យុវជន និងកីឡា ខេត្តបន្ទាយមានជ័យ
A6: =ស្ថិតិលទ្ធផលសិក្សាតាមនិទ្ទេស!A6 -> វិទ្យាល័យចំណេះទូទៅនិងបច្ចេកទេស ឯកជនដុនបូស្កូប៉ោយប៉ែត
A7: តារាងពិន្ទុប្រឡងប្រចាំខែមីនា របស់សិស្សផ្នែក អគ្គិសនី ឆ្នាំទី២
A8: =មេកានិច១!A8 -> ឆ្នាំសិក្សា ២០២៥- ២០២៦
A9: ល.រ | B9: គោត្តនាម | C9: និងនាម | D9: ភេទ | E9: ថ្ងៃខែឆ្នាំកំណើត | G9: មុខវិជ្ជា | Q9: សរុប | R9: មធ្យមភាគ | S9: និទ្ទេស | T9: ចំណាត់ថ្នាក់ | U9: អវត្តមាន
G10: ខ្មែរ | H10: គណិត | I10: រូប​ | J10: អង់គ្លេស | K10: ពលរដ្ឋ | L10: កីឡា | M10: ទ្រឹស្ដីទី១ | N10: ទ្រឹស្ដីទី២ | O10: ផ្ទាល់មាត់ | P10: អនុវត្ត
U11: មានច្បាប់ | V11: អត់ច្បាប់ | W11: សរុប
A12: 1 | B12: ជ្រាង | C12: ឃាងលី | D12: ប | E12: ២៦ មេសា ២០០៧ | G12: 30 | H12: 30 | I12: 15 | J12: 15 | K12: 11 | L12: 20 | M12: 50 | N12: 50 | O12: 70 | P12: 75 | Q12: =SUM(G12:P12)-W12 -> 363 | R12: =Q12/14.5 -> 25.034483 | S12: =IF(R12>=50*0.9,"A",IF(R12>=50*0.8,"B",IF(R12>=50*0.7,"C",IF(R12>=50*0.6,"D",IF(R12>=50*0.5,"E",IF(Q12=0,"NA","F")))))) -> E | T12: =RANK(R12,$R$12:$R$29) -> 17 | U12: 3 | V12: 0 | W12: =SUM(U12:V12) -> 3
A13: 2 | B13: ដន | C13: សុខយី | D13: ស | E13: 39900 | G13: 50 | H13: 59 | I13: 25 | J13: 33 | K13: 21 | L13: 20 | M13: 62 | N13: 87 | O13: 75 | P13: 100 | Q13: =SUM(G13:P13)-W13 -> 531 | R13: =Q13/14.5 -> 36.62069 | S13: =IF(R13>=50*0.9,"A",IF(R13>=50*0.8,"B",IF(R13>=50*0.7,"C",IF(R13>=50*0.6,"D",IF(R13>=50*0.5,"E",IF(Q13=0,"NA","F")))))) -> C | T13: =RANK(R13,$R$12:$R$29) -> 1 | U13: 1 | V13: 0 | W13: =SUM(U13:V13) -> 1
A14: 3 | B14: ណែម | C14: បូរី | D14: ប | E14: 38632 | F14: 38632 | G14: 43 | H14: 54 | I14: 22 | J14: 28 | K14: 24 | L14: 20 | M14: 53 | N14: 63 | O14: 95 | P14: 85 | Q14: =SUM(G14:P14)-W14 -> 487 | R14: =Q14/14.5 -> 33.586207 | S14: =IF(R14>=50*0.9,"A",IF(R14>=50*0.8,"B",IF(R14>=50*0.7,"C",IF(R14>=50*0.6,"D",IF(R14>=50*0.5,"E",IF(Q14=0,"NA","F")))))) -> D | T14: =RANK(R14,$R$12:$R$29) -> 7 | U14: 0 | V14: 0 | W14: =SUM(U14:V14) -> 0
A15: 4 | B15: ថន | C15: វរៈបុត្រ | D15: ប | E15: 39783 | F15: 39783 | G15: 38 | H15: 42 | I15: 15 | J15: 27 | K15: 11 | L15: 20 | M15: 40 | N15: 58 | O15: 70 | P15: 80 | Q15: =SUM(G15:P15)-W15 -> 401 | R15: =Q15/14.5 -> 27.655172 | S15: =IF(R15>=50*0.9,"A",IF(R15>=50*0.8,"B",IF(R15>=50*0.7,"C",IF(R15>=50*0.6,"D",IF(R15>=50*0.5,"E",IF(Q15=0,"NA","F")))))) -> E | T15: =RANK(R15,$R$12:$R$29) -> 13 | U15: 0 | V15: 0 | W15: =SUM(U15:V15) -> 0
A16: 5 | B16: ផាន់ | C16: ស៊ីញអាង | D16: ប | E16: 40102 | G16: 0 | I16: 0 | J16: 0 | K16: 0 | L16: 0 | O16: 0 | P16: 0 | Q16: =SUM(G16:P16)-W16 -> 0 | R16: =Q16/14.5 -> 0 | S16: =IF(R16>=50*0.9,"A",IF(R16>=50*0.8,"B",IF(R16>=50*0.7,"C",IF(R16>=50*0.6,"D",IF(R16>=50*0.5,"E",IF(Q16=0,"NA","F")))))) -> NA | T16: =RANK(R16,$R$12:$R$29) -> 18 | U16: 0 | V16: 0 | W16: =SUM(U16:V16) -> 0
A17: 6 | B17: ផុន | C17: សុផាន់ | D17: ប | E17: 40437 | G17: 40 | H17: 44 | I17: 20 | J17: 37 | K17: 20 | L17: 20 | M17: 29 | N17: 41 | O17: 75 | P17: 90 | Q17: =SUM(G17:P17)-W17 -> 414 | R17: =Q17/14.5 -> 28.551724 | S17: =IF(R17>=50*0.9,"A",IF(R17>=50*0.8,"B",IF(R17>=50*0.7,"C",IF(R17>=50*0.6,"D",IF(R17>=50*0.5,"E",IF(Q17=0,"NA","F")))))) -> E | T17: =RANK(R17,$R$12:$R$29) -> 11 | U17: 2 | V17: 0 | W17: =SUM(U17:V17) -> 2
A18: 7 | B18: មួង | C18: វាសនា | D18: ប | E18: 39158 | G18: 38 | H18: 44 | I18: 21 | J18: 28 | K18: 20 | L18: 20 | M18: 61 | N18: 61 | O18: 95 | P18: 97 | Q18: =SUM(G18:P18)-W18 -> 485 | R18: =Q18/14.5 -> 33.448276 | S18: =IF(R18>=50*0.9,"A",IF(R18>=50*0.8,"B",IF(R18>=50*0.7,"C",IF(R18>=50*0.6,"D",IF(R18>=50*0.5,"E",IF(Q18=0,"NA","F")))))) -> D | T18: =RANK(R18,$R$12:$R$29) -> 8 | U18: 0 | V18: 0 | W18: =SUM(U18:V18) -> 0
A19: 8 | B19: រ៉ា | C19: បញ្ញា | D19: ប | E19: 40074 | F19: 40074 | G19: 43 | H19: 44 | I19: 26 | J19: 35 | K19: 22 | L19: 20 | M19: 67 | N19: 75 | O19: 95 | P19: 85 | Q19: =SUM(G19:P19)-W19 -> 512 | R19: =Q19/14.5 -> 35.310345 | S19: =IF(R19>=50*0.9,"A",IF(R19>=50*0.8,"B",IF(R19>=50*0.7,"C",IF(R19>=50*0.6,"D",IF(R19>=50*0.5,"E",IF(Q19=0,"NA","F")))))) -> C | T19: =RANK(R19,$R$12:$R$29) -> 3 | U19: 0 | V19: 0 | W19: =SUM(U19:V19) -> 0
A20: 9 | B20: រី | C20: សុរិត | D20: ប | E20: 40030 | F20: 40030 | G20: 43 | H20: 49 | I20: 24 | J20: 36 | K20: 19 | L20: 20 | M20: 60 | N20: 63 | O20: 95 | P20: 100 | Q20: =SUM(G20:P20)-W20 -> 509 | R20: =Q20/14.5 -> 35.103448 | S20: =IF(R20>=50*0.9,"A",IF(R20>=50*0.8,"B",IF(R20>=50*0.7,"C",IF(R20>=50*0.6,"D",IF(R20>=50*0.5,"E",IF(Q20=0,"NA","F")))))) -> C | T20: =RANK(R20,$R$12:$R$29) -> 4 | U20: 0 | V20: 0 | W20: =SUM(U20:V20) -> 0
A21: 10 | B21: លីន | C21: វិសាល | D21: ប | E21: 40071 | G21: 38 | H21: 44 | I21: 16 | J21: 46 | K21: 20 | L21: 20 | M21: 24 | N21: 20 | O21: 70 | P21: 85 | Q21: =SUM(G21:P21)-W21 -> 383 | R21: =Q21/14.5 -> 26.413793 | S21: =IF(R21>=50*0.9,"A",IF(R21>=50*0.8,"B",IF(R21>=50*0.7,"C",IF(R21>=50*0.6,"D",IF(R21>=50*0.5,"E",IF(Q21=0,"NA","F")))))) -> E | T21: =RANK(R21,$R$12:$R$29) -> 15 | U21: 0 | V21: 0 | W21: =SUM(U21:V21) -> 0
A22: 11 | B22: សួគ៌ | C22: មេងហ្វូ | D22: ប | E22: ២២ កុម្ភៈ ២០១០ | G22: 39 | H22: 42 | I22: 23 | J22: 38 | K22: 18 | L22: 20 | M22: 71 | N22: 76 | O22: 90 | P22: 115 | Q22: =SUM(G22:O22)-W22 -> 417 | R22: =Q22/14.5 -> 28.758621 | S22: =IF(R22>=50*0.9,"A",IF(R22>=50*0.8,"B",IF(R22>=50*0.7,"C",IF(R22>=50*0.6,"D",IF(R22>=50*0.5,"E",IF(Q22=0,"NA","F")))))) -> E | T22: =RANK(R22,$R$12:$R$29) -> 10 | U22: 0 | V22: 0 | W22: =SUM(U22:V22) -> 0
A23: 12 | B23: សៀង | C23: មករា | D23: ប | E23: 40195 | G23: 40 | H23: 34 | I23: 33 | J23: 34 | K23: 22 | L23: 20 | M23: 68 | N23: 72 | O23: 95 | P23: 110 | Q23: =SUM(G23:P23)-W23 -> 527 | R23: =Q23/14.5 -> 36.344828 | S23: =IF(R23>=50*0.9,"A",IF(R23>=50*0.8,"B",IF(R23>=50*0.7,"C",IF(R23>=50*0.6,"D",IF(R23>=50*0.5,"E",IF(Q23=0,"NA","F")))))) -> C | T23: =RANK(R23,$R$12:$R$29) -> 2 | U23: 1 | V23: 0 | W23: =SUM(U23:V23) -> 1
A24: 13 | B24: ស្រី | C24: ឃុនរ៉ា | D24: ប | E24: 39824 | G24: 40 | H24: 40 | I24: 24 | J24: 35 | K24: 16 | L24: 20 | M24: 78 | N24: 72 | O24: 85 | P24: 85 | Q24: =SUM(G24:P24)-W24 -> 495 | R24: =Q24/14.5 -> 34.137931 | S24: =IF(R24>=50*0.9,"A",IF(R24>=50*0.8,"B",IF(R24>=50*0.7,"C",IF(R24>=50*0.6,"D",IF(R24>=50*0.5,"E",IF(Q24=0,"NA","F")))))) -> D | T24: =RANK(R24,$R$12:$R$29) -> 6 | U24: 0 | V24: 0 | W24: =SUM(U24:V24) -> 0
A25: 14 | B25: ស្រឿន | C25: ប៊ុនធេង | D25: ប | E25: ២៨ មិថុនា​ ២០០៧ | F25: ២៨ មិថុនា​ ២០០៧ | G25: 42 | H25: 45 | I25: 29 | J25: 46 | K25: 18 | L25: 20 | M25: 52 | N25: 34 | O25: 85 | P25: 100 | Q25: =SUM(G25:P25)-W25 -> 471 | R25: =Q25/14.5 -> 32.482759 | S25: =IF(R25>=50*0.9,"A",IF(R25>=50*0.8,"B",IF(R25>=50*0.7,"C",IF(R25>=50*0.6,"D",IF(R25>=50*0.5,"E",IF(Q25=0,"NA","F")))))) -> D | T25: =RANK(R25,$R$12:$R$29) -> 9 | U25: 0 | V25: 0 | W25: =SUM(U25:V25) -> 0
A26: 15 | B26: ហ៊ាន | C26: ម៉េងហួត | D26: ប | E26: 40068 | F26: 40068 | G26: 44 | H26: 39 | I26: 24 | J26: 19 | K26: 13 | L26: 20 | M26: 40 | N26: 53 | O26: 80 | P26: 80 | Q26: =SUM(G26:P26)-W26 -> 412 | R26: =Q26/14.5 -> 28.413793 | S26: =IF(R26>=50*0.9,"A",IF(R26>=50*0.8,"B",IF(R26>=50*0.7,"C",IF(R26>=50*0.6,"D",IF(R26>=50*0.5,"E",IF(Q26=0,"NA","F")))))) -> E | T26: =RANK(R26,$R$12:$R$29) -> 12 | U26: 0 | V26: 0 | W26: =SUM(U26:V26) -> 0
A27: 16 | B27: អេង | C27: លាភហេង | D27: ប | E27: 39751 | F27: 39751 | G27: 39 | H27: 44 | I27: 21 | J27: 15 | K27: 11 | L27: 20 | M27: 25 | N27: 26 | O27: 85 | P27: 100 | Q27: =SUM(G27:P27)-W27 -> 385 | R27: =Q27/14.5 -> 26.551724 | S27: =IF(R27>=50*0.9,"A",IF(R27>=50*0.8,"B",IF(R27>=50*0.7,"C",IF(R27>=50*0.6,"D",IF(R27>=50*0.5,"E",IF(Q27=0,"NA","F")))))) -> E | T27: =RANK(R27,$R$12:$R$29) -> 14 | U27: 1 | V27: 0 | W27: =SUM(U27:V27) -> 1
A28: 17 | B28: អែម | C28: លីហួ | D28: ប | E28: 40246 | F28: 40246 | G28: 39 | H28: 44 | I28: 32 | J28: 35 | K28: 17 | L28: 20 | M28: 58 | N28: 53 | O28: 95 | P28: 105 | Q28: =SUM(G28:P28)-W28 -> 496 | R28: =Q28/14.5 -> 34.206897 | S28: =IF(R28>=50*0.9,"A",IF(R28>=50*0.8,"B",IF(R28>=50*0.7,"C",IF(R28>=50*0.6,"D",IF(R28>=50*0.5,"E",IF(Q28=0,"NA","F")))))) -> D | T28: =RANK(R28,$R$12:$R$29) -> 5 | U28: 2 | V28: 0 | W28: =SUM(U28:V28) -> 2
A29: 18 | B29: អ៊ី | C29: លីហ្វុង | D29: ប | E29: ០៤ មីនា ២០០៩ | G29: 30 | H29: 34 | I29: 15 | J29: 21 | K29: 18 | L29: 20 | M29: 44 | N29: 50 | O29: 70 | P29: 80 | Q29: =SUM(G29:P29)-W29 -> 377 | R29: =Q29/14.5 -> 26 | S29: =IF(R29>=50*0.9,"A",IF(R29>=50*0.8,"B",IF(R29>=50*0.7,"C",IF(R29>=50*0.6,"D",IF(R29>=50*0.5,"E",IF(Q29=0,"NA","F")))))) -> E | T29: =RANK(R29,$R$12:$R$29) -> 16 | U29: 1 | V29: 4 | W29: =SUM(U29:V29) -> 5
A30: ="បញ្ឈប់បញ្ជីត្រឹមឈ្មោះ អ៊ី លីហ្វុង "&" ចំនួនសរុប "&COUNT(A12:A29)&" នាក់"&" ក្នុងនោះស្រី "&COUNTIF(D12:D29,"ស")&" នាក់ ។" -> បញ្ឈប់បញ្ជីត្រឹមឈ្មោះ អ៊ី លីហ្វុង ចំនួនសរុប 18 នាក់ ក្នុងនោះស្រី 1 នាក់ ។
B31: * បញ្ជាក់
B32: លំដាប់ពិន្ទុ | D32: និទ្ទេស | E32: សេចក្តីពណ៌នា
B33: មធ្យមភាគអតិប្បរមា*0.9 | D33: A | E33: ល្អប្រសើរ
B34: មធ្យមភាគអតិប្បរមា*0.8 | D34: B | E34: ល្អណាស់
B35: មធ្យមភាគអតិប្បរមា*0.7 | D35: C | E35: ល្អ
B36: មធ្យមភាគអតិប្បរមា*0.6 | D36: D | E36: ល្អបង្គួ
B37: មធ្យមភាគអតិប្បរមា*0.5 | D37: E | E37: មធ្យម
B38: <មធ្យមភាគអតិប្បរមា*0.5 | D38: F | E38: ខ្សោយ
B39: *** NA គឺសិស្សមិនបានប្រទ្បងសូម្បី១មុខវិជ្ជា ពិន្ទុសរុបស្មើសូន្យ។
A40: សរុបលទ្ធផលតាមនិទ្ទេស | F40: សរុប | G40: ស្រី
...

Sheet កុំព្យូទ័រ២
A1: ព្រះរាជាណាចក្រកម្ពុជា
A2: ជាតិ សាសនា ព្រះមហាក្សត្រ
A3: 6
A4: ក្រសួងអប់រំ យុវជន និងកីឡា | U4: ឧបសម្ព័ន្ធទី២
A5: =ស្ថិតិលទ្ធផលសិក្សាតាមនិទ្ទេស!A5 -> មន្ទីរអប់រំ យុវជន និងកីឡា ខេត្តបន្ទាយមានជ័យ
A6: =ស្ថិតិលទ្ធផលសិក្សាតាមនិទ្ទេស!A6 -> វិទ្យាល័យចំណេះទូទៅនិងបច្ចេកទេស ឯកជនដុនបូស្កូប៉ោយប៉ែត
A7: តារាងពិន្ទុប្រឡងប្រចាំខែមីនា របស់សិស្សផ្នែក កំព្យូទ័​រ ឆ្នាំទី២
A8: =កុំព្យទ័រ៣!A8 -> ឆ្នាំសិក្សា ២០២៥- ២០២៦
A9: ល.រ | B9: គោត្តនាម | C9: និងនាម | D9: ភេទ | E9: ថ្ងៃខែឆ្នាំកំណើត | G9: មុខវិជ្ជា | Q9: សរុប | R9: មធ្យមភាគ | S9: និទ្ទេស | T9: ចំណាត់ថ្នាក់ | U9: អវត្តមាន
G10: ខ្មែរ | H10: គណិត | I10: រូប​ | J10: អង់គ្លេស | K10: ពលរដ្ឋ | L10: កីឡា | M10: ទ្រឹស្ដីទី១ | N10: ទ្រឹស្ដីទី២ | O10: ផ្ទាល់មាត់ | P10: អនុវត្ត
U11: មានច្បាប់ | V11: អត់ច្បាប់ | W11: សរុប
A12: 1 | B12: កែវ | C12: សុផាន់នី | D12: ប | E12: 38779 | G12: 50 | H12: 51 | I12: 28 | J12: 33 | K12: 21 | L12: 20 | M12: 90 | N12: 95 | O12: 93 | P12: 110 | Q12: =SUM(G12:P12)-W12 -> 590 | R12: =Q12/14.5 -> 40.689655 | S12: =IF(R12>=50*0.9,"A",IF(R12>=50*0.8,"B",IF(R12>=50*0.7,"C",IF(R12>=50*0.6,"D",IF(R12>=50*0.5,"E",IF(Q12=0,"NA","F")))))) -> B | T12: =RANK(R12,$R$12:$R$38) -> 8 | U12: 1 | V12: 0 | W12: =SUM(U12:V12) -> 1
A13: 2 | B13: ខៀវ | C13: ហ្គេចណៃ | D13: ស | E13: 39838 | G13: 54 | H13: 44 | I13: 26 | J13: 36 | K13: 24 | L13: 20 | M13: 80 | N13: 100 | O13: 100 | P13: 120 | Q13: =SUM(G13:P13)-W13 -> 602 | R13: =Q13/14.5 -> 41.517241 | S13: =IF(R13>=50*0.9,"A",IF(R13>=50*0.8,"B",IF(R13>=50*0.7,"C",IF(R13>=50*0.6,"D",IF(R13>=50*0.5,"E",IF(Q13=0,"NA","F")))))) -> B | T13: =RANK(R13,$R$12:$R$38) -> 6 | U13: 2 | V13: 0 | W13: =SUM(U13:V13) -> 2
A14: 3 | B14: ចន | C14: ស៊ីណាង | D14: ស | E14: 39507 | G14: 49 | H14: 20 | I14: 25 | J14: 30 | K14: 24 | L14: 20 | M14: 70 | N14: 95 | O14: 88 | P14: 113 | Q14: =SUM(G14:P14)-W14 -> 534 | R14: =Q14/14.5 -> 36.827586 | S14: =IF(R14>=50*0.9,"A",IF(R14>=50*0.8,"B",IF(R14>=50*0.7,"C",IF(R14>=50*0.6,"D",IF(R14>=50*0.5,"E",IF(Q14=0,"NA","F")))))) -> C | T14: =RANK(R14,$R$12:$R$38) -> 19 | U14: 0 | V14: 0 | W14: =SUM(U14:V14) -> 0
A15: 4 | B15: ចាន់ | C15: ស្រីល័ក្ខ | D15: ស | E15: 40143 | G15: 45 | H15: 52 | I15: 40 | J15: 22 | K15: 21 | L15: 20 | M15: 80 | N15: 95 | O15: 95 | P15: 116 | Q15: =SUM(G15:P15)-W15 -> 584 | R15: =Q15/14.5 -> 40.275862 | S15: =IF(R15>=50*0.9,"A",IF(R15>=50*0.8,"B",IF(R15>=50*0.7,"C",IF(R15>=50*0.6,"D",IF(R15>=50*0.5,"E",IF(Q15=0,"NA","F")))))) -> B | T15: =RANK(R15,$R$12:$R$38) -> 9 | U15: 2 | V15: 0 | W15: =SUM(U15:V15) -> 2
A16: 5 | B16: ចាន់ | C16: សុម៉ាវត្តី | D16: ស | E16: 39782 | F16: 39782 | G16: 50 | H16: 27 | I16: 29 | J16: 39 | K16: 24 | L16: 20 | M16: 95 | N16: 90 | O16: 93 | P16: 113 | Q16: =SUM(G16:P16)-W16 -> 576 | R16: =Q16/14.5 -> 39.724138 | S16: =IF(R16>=50*0.9,"A",IF(R16>=50*0.8,"B",IF(R16>=50*0.7,"C",IF(R16>=50*0.6,"D",IF(R16>=50*0.5,"E",IF(Q16=0,"NA","F")))))) -> C | T16: =RANK(R16,$R$12:$R$38) -> 12 | U16: 4 | V16: 0 | W16: =SUM(U16:V16) -> 4
A17: 6 | B17: ចើយ | C17: យុឃាន | D17: ស | E17: 39810 | G17: 50 | H17: 27 | I17: 25 | J17: 29 | K17: 23 | L17: 20 | M17: 85 | N17: 90 | O17: 85 | P17: 113 | Q17: =SUM(G17:P17)-W17 -> 547 | R17: =Q17/14.5 -> 37.724138 | S17: =IF(R17>=50*0.9,"A",IF(R17>=50*0.8,"B",IF(R17>=50*0.7,"C",IF(R17>=50*0.6,"D",IF(R17>=50*0.5,"E",IF(Q17=0,"NA","F")))))) -> C | T17: =RANK(R17,$R$12:$R$38) -> 15 | U17: 0 | V17: 0 | W17: =SUM(U17:V17) -> 0
A18: 7 | B18: ឆាន់ | C18: ស៊ីវម៉ី | D18: ស | E18: 40030 | G18: 49 | H18: 44 | I18: 26 | J18: 35 | K18: 25 | L18: 20 | M18: 90 | N18: 100 | O18: 100 | P18: 122 | Q18: =SUM(G18:P18)-W18 -> 611 | R18: =Q18/14.5 -> 42.137931 | S18: =IF(R18>=50*0.9,"A",IF(R18>=50*0.8,"B",IF(R18>=50*0.7,"C",IF(R18>=50*0.6,"D",IF(R18>=50*0.5,"E",IF(Q18=0,"NA","F")))))) -> B | T18: =RANK(R18,$R$12:$R$38) -> 4 | U18: 0 | V18: 0 | W18: =SUM(U18:V18) -> 0
A19: 8 | B19: ឆាយ | C19: មីនា | D19: ស | E19: 39886 | F19: 39886 | G19: 50 | H19: 49 | I19: 38 | J19: 36 | K19: 24 | L19: 20 | M19: 95 | N19: 100 | O19: 100 | P19: 113 | Q19: =SUM(G19:P19)-W19 -> 625 | R19: =Q19/14.5 -> 43.103448 | S19: =IF(R19>=50*0.9,"A",IF(R19>=50*0.8,"B",IF(R19>=50*0.7,"C",IF(R19>=50*0.6,"D",IF(R19>=50*0.5,"E",IF(Q19=0,"NA","F")))))) -> B | T19: =RANK(R19,$R$12:$R$38) -> 2 | U19: 0 | V19: 0 | W19: =SUM(U19:V19) -> 0
A20: 9 | B20: ជីន | C20: ធារ៉ា | D20: ប | E20: 39790 | F20: 39790 | G20: 30 | H20: 49 | I20: 28 | J20: 30 | K20: 24 | L20: 20 | M20: 80 | N20: 85 | O20: 88 | P20: 114 | Q20: =SUM(G20:P20)-W20 -> 546 | R20: =Q20/14.5 -> 37.655172 | S20: =IF(R20>=50*0.9,"A",IF(R20>=50*0.8,"B",IF(R20>=50*0.7,"C",IF(R20>=50*0.6,"D",IF(R20>=50*0.5,"E",IF(Q20=0,"NA","F")))))) -> C | T20: =RANK(R20,$R$12:$R$38) -> 17 | U20: 2 | V20: 0 | W20: =SUM(U20:V20) -> 2
A21: 10 | B21: ឈឿន | C21: មេសា | D21: ប | E21: 39902 | F21: 39902 | G21: 30 | H21: 49 | I21: 27 | J21: 30 | K21: 24 | L21: 20 | M21: 75 | N21: 85 | O21: 90 | P21: 116 | Q21: =SUM(G21:P21)-W21 -> 542 | R21: =Q21/14.5 -> 37.37931 | S21: =IF(R21>=50*0.9,"A",IF(R21>=50*0.8,"B",IF(R21>=50*0.7,"C",IF(R21>=50*0.6,"D",IF(R21>=50*0.5,"E",IF(Q21=0,"NA","F")))))) -> C | T21: =RANK(R21,$R$12:$R$38) -> 18 | U21: 3 | V21: 1 | W21: =SUM(U21:V21) -> 4
A22: 11 | B22: តាន់ | C22: ផេងអាន | D22: ស | E22: 39971 | F22: 39971 | G22: 39 | H22: 40 | I22: 24 | J22: 42 | K22: 23 | L22: 20 | M22: 70 | N22: 70 | O22: 60 | P22: 108 | Q22: =SUM(G22:P22)-W22 -> 488 | R22: =Q22/14.5 -> 33.655172 | S22: =IF(R22>=50*0.9,"A",IF(R22>=50*0.8,"B",IF(R22>=50*0.7,"C",IF(R22>=50*0.6,"D",IF(R22>=50*0.5,"E",IF(Q22=0,"NA","F")))))) -> D | T22: =RANK(R22,$R$12:$R$38) -> 23 | U22: 7 | V22: 1 | W22: =SUM(U22:V22) -> 8
A23: 12 | B23: ធរ៍ | C23: វិធាន | D23: ស | E23: 39561 | F23: 39561 | G23: 45 | H23: 39 | I23: 36 | J23: 27 | K23: 21 | L23: 20 | M23: 65 | N23: 90 | O23: 70 | P23: 120 | Q23: =SUM(G23:P23)-W23 -> 532 | R23: =Q23/14.5 -> 36.689655 | S23: =IF(R23>=50*0.9,"A",IF(R23>=50*0.8,"B",IF(R23>=50*0.7,"C",IF(R23>=50*0.6,"D",IF(R23>=50*0.5,"E",IF(Q23=0,"NA","F")))))) -> C | T23: =RANK(R23,$R$12:$R$38) -> 20 | U23: 1 | V23: 0 | W23: =SUM(U23:V23) -> 1
A24: 13 | B24: នី | C24: ស្រីពេជ | D24: ស | E24: 39266 | F24: 39266 | G24: 54 | H24: 40 | I24: 29 | J24: 32 | K24: 22 | L24: 20 | M24: 90 | N24: 95 | O24: 83 | P24: 103 | Q24: =SUM(G24:P24)-W24 -> 568 | R24: =Q24/14.5 -> 39.172414 | S24: =IF(R24>=50*0.9,"A",IF(R24>=50*0.8,"B",IF(R24>=50*0.7,"C",IF(R24>=50*0.6,"D",IF(R24>=50*0.5,"E",IF(Q24=0,"NA","F")))))) -> C | T24: =RANK(R24,$R$12:$R$38) -> 13 | U24: 0 | V24: 0 | W24: =SUM(U24:V24) -> 0
A25: 14 | B25: នីម | C25: ស្រីណូ | D25: ស | E25: 39794 | F25: 39794 | G25: 49 | H25: 47 | I25: 28 | J25: 33 | K25: 25 | L25: 20 | M25: 90 | N25: 95 | O25: 93 | P25: 113 | Q25: =SUM(G25:P25)-W25 -> 593 | R25: =Q25/14.5 -> 40.896552 | S25: =IF(R25>=50*0.9,"A",IF(R25>=50*0.8,"B",IF(R25>=50*0.7,"C",IF(R25>=50*0.6,"D",IF(R25>=50*0.5,"E",IF(Q25=0,"NA","F")))))) -> B | T25: =RANK(R25,$R$12:$R$38) -> 7 | U25: 0 | V25: 0 | W25: =SUM(U25:V25) -> 0
A26: 15 | B26: ផន | C26: ស៊ីណា | D26: ប | E26: 39719 | F26: 39719 | G26: 59 | H26: 27 | I26: 37 | J26: 30 | K26: 22 | L26: 20 | M26: 60 | N26: 70 | O26: 75 | P26: 109 | Q26: =SUM(G26:P26)-W26 -> 507 | R26: =Q26/14.5 -> 34.965517 | S26: =IF(R26>=50*0.9,"A",IF(R26>=50*0.8,"B",IF(R26>=50*0.7,"C",IF(R26>=50*0.6,"D",IF(R26>=50*0.5,"E",IF(Q26=0,"NA","F")))))) -> D | T26: =RANK(R26,$R$12:$R$38) -> 22 | U26: 2 | V26: 0 | W26: =SUM(U26:V26) -> 2
A27: 16 | B27: យ៉ង | C27: សៀវយីង | D27: ស | E27: 40044 | F27: 40044 | G27: 30 | H27: 40 | I27: 20 | J27: 48 | K27: 21 | L27: 20 | M27: 65 | N27: 70 | O27: 70 | P27: 83 | Q27: =SUM(G27:P27)-W27 -> 457 | R27: =Q27/14.5 -> 31.517241 | S27: =IF(R27>=50*0.9,"A",IF(R27>=50*0.8,"B",IF(R27>=50*0.7,"C",IF(R27>=50*0.6,"D",IF(R27>=50*0.5,"E",IF(Q27=0,"NA","F")))))) -> D | T27: =RANK(R27,$R$12:$R$38) -> 27 | U27: 10 | V27: 0 | W27: =SUM(U27:V27) -> 10
A28: 17 | B28: យ៉ាន | C28: សុវណ្ណណយ | D28: ប | E28: 40022 | F28: 40022 | G28: 30 | H28: 27 | I28: 24 | J28: 30 | K28: 21 | L28: 20 | M28: 65 | N28: 90 | O28: 85 | P28: 90 | Q28: =SUM(G28:P28)-W28 -> 479 | R28: =Q28/14.5 -> 33.034483 | S28: =IF(R28>=50*0.9,"A",IF(R28>=50*0.8,"B",IF(R28>=50*0.7,"C",IF(R28>=50*0.6,"D",IF(R28>=50*0.5,"E",IF(Q28=0,"NA","F")))))) -> D | T28: =RANK(R28,$R$12:$R$38) -> 24 | U28: 3 | V28: 0 | W28: =SUM(U28:V28) -> 3
A29: 18 | B29: យាង | C29: ណាវី | D29: ស | E29: 40169 | F29: 40169 | G29: 42 | H29: 34 | I29: 24 | J29: 32 | K29: 25 | L29: 20 | M29: 95 | N29: 95 | O29: 98 | P29: 121 | Q29: =SUM(G29:P29)-W29 -> 584 | R29: =Q29/14.5 -> 40.275862 | S29: =IF(R29>=50*0.9,"A",IF(R29>=50*0.8,"B",IF(R29>=50*0.7,"C",IF(R29>=50*0.6,"D",IF(R29>=50*0.5,"E",IF(Q29=0,"NA","F")))))) -> B | T29: =RANK(R29,$R$12:$R$38) -> 9 | U29: 2 | V29: 0 | W29: =SUM(U29:V29) -> 2
